Workbook

Sheet README
A1: Data cleaning and validation exercises (Phase 3)
A2: Independent portfolio project. Not an official IRCTC or Indian Railways system. All data is synthetic.
A3: SYNTHETIC DATA. Sampled simulation: 768 simulated train runs, compared with 19,708 scheduled runs in the modelled schedule (3.9%). Not a representative full railway schedule and not IRCTC or Indian Railways network-wide metrics.
A5: Sample: 647 raw booking rows, 1,335 passenger rows, 178 cancellation rows, 91 capacity rows, 55 operations rows, taken from data/raw/synthetic (never edited). It is enriched so that every one of the 30 issue types appears; real defect rates in the full raw extract are about 1% or less.
A6: Raw_* sheets hold the extract as delivered. Plain numbers are stored as numbers (as an Excel CSV import would); currency text such as '₹1,250.00', DD-MM-YYYY dates and alias statuses stay text.
A7: Exercises: work through the list (Beginner to Advanced). Try each on the Raw_* sheets first, then compare with the Work_* sheets, which hold one flag column per issue.
A8: Answer_Key: expected counts (independent detection by the Python cleaner) beside the Excel formula counts. All formula counts should match; total_fare_invalid is a manual exercise.
A9: Clean_*_Solution: the cleaned result for these rows. Validation_Checks: formula checks (duplicates, statuses, BR-03 sums, BR-04 dates, orphans). Paste your own cleaned tables there to test them.
A10: Cleaning rules never invent data: unrecoverable records are rejected with their whole booking family; missing age band becomes 'Unknown' and missing delays stay blank. See docs/data_quality_report.md.
A11: XLOOKUP is not used: it could not be verified in the build environment. The worked solution uses INDEX/MATCH and SUMPRODUCT lookups that work in every Excel version and in Google Sheets. In Excel 365 you may practise the same lookups with XLOOKUP.

Sheet Exercises
A1: Data cleaning exercises
A2: SYNTHETIC DATA. Sampled simulation: 768 simulated train runs, compared with 19,708 scheduled runs in the modelled schedule (3.9%). Not a representative full railway schedule and not IRCTC or Indian Railways network-wide metrics.
A3: # | B3: Level | C3: Issue code | D3: Sheet | E3: Problem to find | F3: Cleaning rule to apply | G3: Suggested functions | H3: Expected count in this sample
A4: 1 | B4: Beginner | C4: dup_booking_rows | D4: Raw_Bookings | E4: Exact re-ingested copies of a booking row (same booking_id) | F4: Keep the first occurrence per booking_id; remove the extra copies | G4: COUNTIF (expanding range), Remove Duplicates | H4: 9
A5: 2 | B5: Beginner | C5: dup_passenger_rows | D5: Raw_Passengers | E5: Exact re-ingested copies of a passenger row (same passenger_id) | F5: Keep the first occurrence per passenger_id; remove the extra copies | G5: COUNTIF, Remove Duplicates | H5: 8
A6: 3 | B6: Beginner | C6: dup_cancellation_rows | D6: Raw_Cancellations | E6: Exact re-ingested copies of a cancellation event (same cancellation_id) | F6: Keep the first occurrence per cancellation_id; remove the extra copies | G6: COUNTIF, Remove Duplicates | H6: 6
A7: 4 | B7: Beginner | C7: missing_total_fare | D7: Raw_Bookings | E7: total_fare is blank | F7: Recompute as SUM(passenger fare_amount) for the booking (BR-03) | G7: TRIM, IF, ISBLANK / LEN | H7: 8
A8: 5 | B8: Intermediate | C8: total_fare_currency_format | D8: Raw_Bookings | E8: total_fare stored as text such as '₹1,250.00' or 'Rs. 1250' | F8: Strip symbols and separators, parse, and verify it equals the passenger fare sum | G8: ISTEXT, SUBSTITUTE, VALUE, IFERROR | H8: 7
A9: 6 | B9: Advanced (manual) | C9: total_fare_invalid | D9: Raw_Bookings + Raw_Passengers | E9: total_fare is negative, zero, non-numeric or does not equal the passenger fare sum | F9: Replace with SUM(passenger fare_amount) when all passenger fares are valid | G9: SUMIFS over passengers, ISNUMBER, comparison; watch negative passenger fares and duplicate passenger rows | H9: 8
A10: 7 | B10: Beginner | C10: negative_passenger_fare | D10: Raw_Passengers | E10: A passenger fare_amount is negative or non-numeric | F10: Reconstruct as booking total_fare minus the other passengers' fares; accept only if positive | G10: ISNUMBER, IF | H10: 8
A11: 8 | B11: Beginner | C11: missing_route_id | D11: Raw_Bookings | E11: route_id is blank | F11: Derive from trains.route_id for the booking's train | G11: TRIM, IF | H11: 9
A12: 9 | B12: Intermediate | C12: num_passengers_invalid | D12: Raw_Bookings | E12: num_passengers blank, non-numeric, or different from the number of passenger rows | F12: Set to the number of passenger rows for the booking (BR-03) | G12: COUNTIFS on non-duplicate passenger rows, ISNUMBER | H12: 6
A13: 10 | B13: Beginner | C13: missing_age_band | D13: Raw_Passengers | E13: age_band is blank | F13: Set to 'Unknown'; no age is imputed. Age band is not used by any KPI | G13: TRIM, IF | H13: 8
A14: 11 | B14: Beginner | C14: station_code_format | D14: Raw_Bookings | E14: boarding/destination station code in lower case or padded with spaces | F14: Trim, upper-case, and map to station_id | G14: TRIM, UPPER, EXACT, COUNTIF against Lookup_Stations | H14: 9
A15: 12 | B15: Beginner | C15: station_code_unknown | D15: Raw_Bookings | E15: station code not present in the station master (e.g. 'XXX', '000', 'N/A') | F15: Derive boarding/destination station from the booking's route (BR-06) | G15: COUNTIF against Lookup_Stations | H15: 6
... A33: 30 | B33: Beginner | C33: delay_out_of_range | D33: Raw_Operations | E33: arrival_delay_min outside the sanity range -60..1440 minutes | F33: Set to NULL and retain the run; excluded from delay KPIs | G33: ISNUMBER, OR | H33: 8

Sheet Answer_Key
A1: Answer key: expected issue counts in THIS sample versus your Excel formulas
A2: Expected = the cleaner's independent detection (python/src/clean_data.py) on exactly these rows. Injected = rows recorded in the injection log for this sample. Excel = the worked-solution formula count. SYNTHETIC DATA. The sample is deliberately enriched with defects and is not a guide to real defect rates.
A4: Issue code | B4: Table | C4: Issue type | D4: Expected (independent detection) | E4: Injected in sample (log) | F4: Excel formula count | G4: Result | H4: Outcome | I4: Cleaning rule
A5: dup_booking_rows | B5: bookings | C5: Duplicate booking rows | D5: 9 | E5: 9 | F5: =SUM(Work_Bookings!$B$2:$B$648) -> 9 | G5: =IF(F5=D5,"PASS","FAIL") -> PASS | H5: rejected | I5: Keep the first occurrence per booking_id; remove the extra copies
A6: dup_passenger_rows | B6: booking_passengers | C6: Duplicate passenger rows | D6: 8 | E6: 8 | F6: =SUM(Work_Passengers!$C$2:$C$1336) -> 8 | G6: =IF(F6=D6,"PASS","FAIL") -> PASS | H6: rejected | I6: Keep the first occurrence per passenger_id; remove the extra copies
A7: dup_cancellation_rows | B7: cancellations | C7: Duplicate cancellation rows | D7: 6 | E7: 6 | F7: =SUM(Work_Cancellations!$B$2:$B$179) -> 6 | G7: =IF(F7=D7,"PASS","FAIL") -> PASS | H7: rejected | I7: Keep the first occurrence per cancellation_id; remove the extra copies
A8: missing_total_fare | B8: bookings | C8: Missing booking total fare | D8: 8 | E8: 8 | F8: =SUM(Work_Bookings!$Y$2:$Y$648) -> 8 | G8: =IF(F8=D8,"PASS","FAIL") -> PASS | H8: corrected | I8: Recompute as SUM(passenger fare_amount) for the booking (BR-03)
A9: total_fare_currency_format | B9: bookings | C9: Fare stored with currency symbol | D9: 7 | E9: 7 | F9: =SUM(Work_Bookings!$AB$2:$AB$648) -> 7 | G9: =IF(F9=D9,"PASS","FAIL") -> PASS | H9: corrected | I9: Strip symbols and separators, parse, and verify it equals the passenger fare sum
A10: total_fare_invalid | B10: bookings | C10: Invalid booking total fare | D10: 8 | E10: 8 | F10: manual exercise | G10: MANUAL | H10: corrected | I10: Replace with SUM(passenger fare_amount) when all passenger fares are valid
A11: negative_passenger_fare | B11: booking_passengers | C11: Invalid passenger fare | D11: 8 | E11: 8 | F11: =SUM(Work_Passengers!$E$2:$E$1336) -> 8 | G11: =IF(F11=D11,"PASS","FAIL") -> PASS | H11: corrected | I11: Reconstruct as booking total_fare minus the other passengers' fares; accept only if positive
A12: missing_route_id | B12: bookings | C12: Missing route reference | D12: 9 | E12: 9 | F12: =SUM(Work_Bookings!$U$2:$U$648) -> 9 | G12: =IF(F12=D12,"PASS","FAIL") -> PASS | H12: corrected | I12: Derive from trains.route_id for the booking's train
A13: num_passengers_invalid | B13: bookings | C13: Invalid passenger count | D13: 6 | E13: 6 | F13: =SUM(Work_Bookings!$AC$2:$AC$648) -> 6 | G13: =IF(F13=D13,"PASS","FAIL") -> PASS | H13: corrected | I13: Set to the number of passenger rows for the booking (BR-03)
A14: missing_age_band | B14: booking_passengers | C14: Missing age band | D14: 8 | E14: 8 | F14: =SUM(Work_Passengers!$F$2:$F$1336) -> 8 | G14: =IF(F14=D14,"PASS","FAIL") -> PASS | H14: retained | I14: Set to 'Unknown'; no age is imputed. Age band is not used by any KPI
A15: station_code_format | B15: bookings | C15: Inconsistent station code format | D15: 9 | E15: 9 | F15: =SUM(Work_Bookings!$S$2:$S$648) -> 9 | G15: =IF(F15=D15,"PASS","FAIL") -> PASS | H15: corrected | I15: Trim, upper-case, and map to station_id
A16: station_code_unknown | B16: bookings | C16: Unknown station code | D16: 6 | E16: 6 | F16: =SUM(Work_Bookings!$T$2:$T$648) -> 6 | G16: =IF(F16=D16,"PASS","FAIL") -> PASS | H16: corrected | I16: Derive boarding/destination station from the booking's route (BR-06)
A17: missing_booking_ts | B17: bookings | C17: Missing booking timestamp | D17: 6 | E17: 6 | F17: =SUM(Work_Bookings!$L$2:$L$648) -> 6 | G17: =IF(F17=D17,"PASS","FAIL") -> PASS | H17: rejected | I17: Cannot be recovered without inventing a value; reject the booking family
A18: journey_date_format | B18: bookings | C18: Journey date in DD-MM-YYYY format | D18: 8 | E18: 8 | F18: =SUM(Work_Bookings!$J$2:$J$648) -> 8 | G18: =IF(F18=D18,"PASS","FAIL") -> PASS | H18: corrected | I18: Parse the unambiguous DD-MM-YYYY pattern and store as ISO date
A19: journey_date_impossible | B19: bookings | C19: Impossible journey date | D19: 6 | E19: 6 | F19: =SUM(Work_Bookings!$K$2:$K$648) -> 6 | G19: =IF(F19=D19,"PASS","FAIL") -> PASS | H19: rejected | I19: Cannot be recovered; reject the booking family
A20: booking_after_journey | B20: bookings | C20: Booking after journey date | D20: 7 | E20: 7 | F20: =SUM(Work_Bookings!$N$2:$N$648) -> 7 | G20: =IF(F20=D20,"PASS","FAIL") -> PASS | H20: rejected | I20: Booking must precede travel (BR-04); the true value is unknown, so reject the booking family
A21: cancellation_before_booking | B21: cancellations | C21: Cancellation before booking | D21: 6 | E21: 6 | F21: =SUM(Work_Cancellations!$I$2:$I$179) -> 6 | G21: =IF(F21=D21,"PASS","FAIL") -> PASS | H21: rejected | I21: Violates BR-12; the true value is unknown, so reject the booking family
A22: booking_status_alias | B22: bookings | C22: Booking status alias | D22: 11 | E22: 11 | F22: =SUM(Work_Bookings!$W$2:$W$648) -> 11 | G22: =IF(F22=D22,"PASS","FAIL") -> PASS | H22: corrected | I22: Map the alias to the canonical status; verified against the passenger roll-up (BR-02)
A23: booking_status_invalid | B23: bookings | C23: Invalid booking status | D23: 8 | E23: 8 | F23: =SUM(Work_Bookings!$X$2:$X$648) -> 8 | G23: =IF(F23=D23,"PASS","FAIL") -> PASS | H23: corrected | I23: Recompute from the passengers' final_status roll-up (BR-02)
A24: passenger_status_alias | B24: booking_passengers | C24: Passenger status alias | D24: 9 | E24: 9 | F24: =SUM(Work_Passengers!$K$2:$K$1336) -> 9 | G24: =IF(F24=D24,"PASS","FAIL") -> PASS | H24: corrected | I24: Map the alias to the canonical status
A25: passenger_final_status_invalid | B25: booking_passengers | C25: Invalid passenger final status | D25: 6 | E25: 6 | F25: =SUM(Work_Passengers!$M$2:$M$1336) -> 6 | G25: =IF(F25=D25,"PASS","FAIL") -> PASS | H25: corrected | I25: Derive from the linked cancellation event: Passenger event -> Cancelled, System event -> Waitlisted (BR-10)
A26: passenger_initial_status_invalid | B26: booking_passengers | C26: Invalid passenger initial status | D26: 6 | E26: 6 | F26: =SUM(Work_Passengers!$L$2:$L$1336) -> 6 | G26: =IF(F26=D26,"PASS","FAIL") -> PASS | H26: rejected | I26: The status at booking time cannot be derived; reject the booking family
A27: orphan_cancellation_rows | B27: cancellations | C27: Cancellation without a valid booking | D27: 6 | E27: 6 | F27: =SUM(Work_Cancellations!$C$2:$C$179) -> 6 | G27: =IF(F27=D27,"PASS","FAIL") -> PASS | H27: rejected | I27: Reject the cancellation row (no valid booking reference)
A28: orphan_passenger_rows | B28: booking_passengers | C28: Passenger without a valid booking | D28: 6 | E28: 6 | F28: =SUM(Work_Passengers!$D$2:$D$1336) -> 6 | G28: =IF(F28=D28,"PASS","FAIL") -> PASS | H28: rejected | I28: Reject the passenger row
A29: refund_exceeds_fare | B29: cancellations | C29: Refund exceeds original fare | D29: 6 | E29: 6 | F29: =SUM(Work_Cancellations!$D$2:$D$179) -> 6 | G29: =IF(F29=D29,"PASS","FAIL") -> PASS | H29: corrected | I29: Recompute refund_amount = original_fare_amount - cancellation_charge (BR-11)
A30: capacity_total_mismatch | B30: seat_capacity | C30: Capacity total inconsistent | D30: 11 | E30: 11 | F30: =SUM(Work_Capacity!$F$2:$F$92) -> 11 | G30: =IF(F30=D30,"PASS","FAIL") -> PASS | H30: corrected | I30: Set total_seats = coaches_attached x seats_per_coach (BR-09)
A31: capacity_seats_per_coach_invalid | B31: seat_capacity | C31: Seats per coach off class standard | D31: 8 | E31: 8 | F31: =SUM(Work_Capacity!$G$2:$G$92) -> 8 | G31: =IF(F31=D31,"PASS","FAIL") -> PASS | H31: corrected | I31: Restore the class-standard seats_per_coach (total_seats already equals coaches x standard)
A32: capacity_conflicting_duplicate | B32: seat_capacity | C32: Conflicting duplicate capacity record | D32: 8 | E32: 8 | F32: =SUM(Work_Capacity!$E$2:$E$92) -> 8 | G32: =IF(F32=D32,"PASS","FAIL") -> PASS | H32: rejected | I32: Keep the internally consistent row; reject the inconsistent one
A33: missing_arrival_delay | B33: train_operations | C33: Missing arrival delay | D33: 8 | E33: 8 | F33: =SUM(Work_Operations!$B$2:$B$56) -> 8 | G33: =IF(F33=D33,"PASS","FAIL") -> PASS | H33: retained | I33: Retain the run with NULL delay; excluded from delay KPIs, never imputed
A34: delay_out_of_range | B34: train_operations | C34: Arrival delay out of range | D34: 8 | E34: 8 | F34: =SUM(Work_Operations!$C$2:$C$56) -> 8 | G34: =IF(F34=D34,"PASS","FAIL") -> PASS | H34: retained | I34: Set to NULL and retain the run; excluded from delay KPIs
C36: Summary | D36: =IF(COUNTIF(G5:G34,"FAIL")=0,"ALL FORMULA COUNTS MATCH ("&COUNTIF(G5:G34,"PASS")&" of 29; 1 manual)","FAILURES: "&COUNTIF(G5:G34,"FAIL")) -> ALL FORMULA COUNTS MATCH (29 of 29; 1 manual)

Sheet Validation_Checks
A1: Validation checks on the cleaned tables
A2: SYNTHETIC DATA. These formulas read Clean_Bookings_Solution and Clean_Passengers_Solution. Paste your own cleaned tables over those sheets (same columns) and every check should read PASS.
A4: # | B4: Check | C4: Result
A5: 1 | B5: No duplicate booking_id in the cleaned bookings | C5: =IF(SUMPRODUCT(--(COUNTIF(Clean_Bookings_Solution!$A$2:$A$608,Clean_Bookings_Solution!$A$2:$A$608)>1))=0,"PASS","FAIL") -> PASS
A6: 2 | B6: No duplicate passenger_id in the cleaned passengers | C6: =IF(SUMPRODUCT(--(COUNTIF(Clean_Passengers_Solution!$A$2:$A$1259,Clean_Passengers_Solution!$A$2:$A$1259)>1))=0,"PASS","FAIL") -> PASS
A7: 3 | B7: Every booking_status is Confirmed, RAC, Waitlisted, Cancelled or Mixed | C7: =IF(SUMPRODUCT(--((Clean_Bookings_Solution!$K$2:$K$608<>"Confirmed")*(Clean_Bookings_Solution!$K$2:$K$608<>"RAC")*(Clean_Bookings_Solution!$K$2:$K$608<>"Waitlisted")*(Clean_Bookings_Solution!$K$2:$K$608<>"Cancelled")*(Clean_Bookings_Solution!$K$2:$K$608<>"Mixed")))=0,"PASS","FAIL") -> PASS
A8: 4 | B8: BR-03: num_passengers equals the passenger rows of each booking | C8: =IF(SUMPRODUCT(--(Clean_Bookings_Solution!$J$2:$J$608<>COUNTIF(Clean_Passengers_Solution!$B$2:$B$1259,Clean_Bookings_Solution!$A$2:$A$608)))=0,"PASS","FAIL") -> PASS
A9: 5 | B9: BR-03: total_fare equals the sum of the passengers' fares | C9: =IF(SUMPRODUCT(--(ABS(Clean_Bookings_Solution!$L$2:$L$608-SUMIF(Clean_Passengers_Solution!$B$2:$B$1259,Clean_Bookings_Solution!$A$2:$A$608,Clean_Passengers_Solution!$E$2:$E$1259))>0.005))=0,"PASS","FAIL") -> PASS
A10: 6 | B10: No passenger without a booking | C10: =IF(SUMPRODUCT(--(COUNTIF(Clean_Bookings_Solution!$A$2:$A$608,Clean_Passengers_Solution!$B$2:$B$1259)=0))=0,"PASS","FAIL") -> PASS
A11: 7 | B11: All fares are positive | C11: =IF(AND(MIN(Clean_Bookings_Solution!$L$2:$L$608)>0,MIN(Clean_Passengers_Solution!$E$2:$E$1259)>0),"PASS","FAIL") -> PASS
A12: 8 | B12: Journey dates are inside 2024-09-01 to 2026-08-31 | C12: =IF(AND(MIN(Clean_Bookings_Solution!$D$2:$D$608)>=DATE(2024,9,1),MAX(Clean_Bookings_Solution!$D$2:$D$608)<=DATE(2026,8,31)),"PASS","FAIL") -> PASS
A13: 9 | B13: BR-04: every booking timestamp is on or before its journey date | C13: =IF(SUMPRODUCT(--(INT(Clean_Bookings_Solution!$I$2:$I$608)>Clean_Bookings_Solution!$D$2:$D$608))=0,"PASS","FAIL") -> PASS
A14: 10 | B14: BR-06: boarding and destination stations differ | C14: =IF(SUMPRODUCT(--(Clean_Bookings_Solution!$F$2:$F$608=Clean_Bookings_Solution!$G$2:$G$608))=0,"PASS","FAIL") -> PASS
A15: 11 | B15: BR-01: passenger statuses are in the allowed domains | C15: =IF(SUMPRODUCT(--((Clean_Passengers_Solution!$G$2:$G$1259<>"Confirmed")*(Clean_Passengers_Solution!$G$2:$G$1259<>"RAC")*(Clean_Passengers_Solution!$G$2:$G$1259<>"Waitlisted")*(Clean_Passengers_Solution!$G$2:$G$1259<>"Cancelled")))=0,"PASS","FAIL") -> PASS
B17: OVERALL | C17: =IF(COUNTIF(C5:C15,"FAIL")=0,"ALL 11 CHECKS PASS","FAILURES: "&COUNTIF(C5:C15,"FAIL")) -> ALL 11 CHECKS PASS

Sheet Lookup_Stations
A1: station_code | B1: station_id | D1: SYNTHETIC reference data.
A2: DEL | B2: 1
A3: JAI | B3: 2
A4: LUC | B4: 3
A5: CHA | B5: 4
A6: AMR | B6: 5
A7: DEH | B7: 6
A8: VAR | B8: 7
A9: JOD | B9: 8
A10: MUM | B10: 9
A11: PUN | B11: 10
A12: AHM | B12: 11
A13: SUR | B13: 12
... A33: DIB | B33: 32

Sheet Lookup_Status
A1: variant (trimmed, lower case) | B1: canonical status | D1: SYNTHETIC reference data.
A2: can | B2: Cancelled
A3: canceled | B3: Cancelled
A4: cancelled | B4: Cancelled
A5: cnf | B5: Confirmed
A6: conf | B6: Confirmed
A7: confirmed | B7: Confirmed
A8: mixed | B8: Mixed
A9: rac | B9: RAC
A10: wait-listed | B10: Waitlisted
A11: waitlist | B11: Waitlisted
A12: waitlisted | B12: Waitlisted
A13: wl | B13: Waitlisted

Sheet Lookup_Class
A1: travel_class | B1: standard seats per coach | D1: SYNTHETIC reference data.
A2: 1A | B2: 24
A3: 2A | B3: 46
A4: 3A | B4: 64
A5: SL | B5: 72
A6: CC | B6: 78
A7: 2S | B7: 108

Sheet Raw_Bookings
A1: booking_id | B1: booking_reference | C1: train_id | D1: journey_date | E1: route_id | F1: boarding_station_code | G1: destination_station_code | H1: travel_class | I1: booking_ts | J1: num_passengers | K1: booking_status | L1: total_fare | M1: data_origin
A2: 1000611 | B2: SB621249971 | C2: 4 | D2: 2024-09-04 | E2: 2 | F2: MAU | G2: DEL | H2: 2S | I2: 2024-06-27 20:12:29 | J2: 4 | K2: Confirmed | L2: 4731 | M2: SYNTHETIC
A3: 1001896 | B3: SB571202856 | C3: 21 | D3: 2024-09-16 | E3: 15 | F3: DEH | G3: PUN | H3: SL | I3: 2024-07-26 15:47:31 | J3: 3 | K3: Confirmed | L3: 3159 | M3: SYNTHETIC
A4: 1002009 | B4: SB522443849 | C4: 31 | D4: 2024-10-15 | F4: MUM | G4: BEN | H4: 2S | I4: 2024-07-28 09:25:14 | J4: 2 | K4: Confirmed | L4: 816 | M4: SYNTHETIC
A5: 1002389 | B5: SB208033029 | C5: 33 | D5: 2024-11-12 | E5: 25 | F5: AHM | G5: CHE | H5: 2S | I5: 2024-08-02 08:15:53 | J5: 2 | K5: Confirmed | L5: 1308 | M5: SYNTHETIC
A6: 1002524 | B6: SB556860764 | C6: 44 | D6: 2024-09-28 | E6: 34 | F6: KOL | G6: HYD | H6: 3A | I6: 2024-08-03 12:31:15 | J6: 2 | K6: Confirmed | L6: 4804 | M6: SYNTHETIC
A7: 1002921 | B7: SB367857881 | C7: 12 | D7: 2024-10-13 | E7: 8 | F7: RAI | G7: JAI | H7: 3A | I7: 2024-08-07 18:54:54 | J7: 2 | K7: Confirmed | L7: 37080 | M7: SYNTHETIC
A8: 1002990 | B8: SB523925390 | C8: 36 | D8: 2024-10-06 | E8: 26 | F8: CHE | G8: AHM | H8: SL | I8: 2024-08-08 12:25:53 | J8: 1 | K8: Confirmed | L8: 1049 | M8: SYNTHETIC
A9: 1003061 | B9: SB988864421 | C9: 30 | D9: 2024-12-04 | E9: 24 | F9: BEN | G9: MUM | H9: 2S | I9: 2024-08-09 07:47:10 | J9: 2 | K9: Confirmed | L9: 1088 | M9: SYNTHETIC
A10: 1003110 | B10: SB056216710 | C10: 4 | D10: 2024-09-04 | E10: 2 | F10: MAU | G10: DEL | H10: 2S | I10: 2024-08-09 15:00:16 | J10: 4 | K10: Confirmed | L10: 5256 | M10: SYNTHETIC
A11: 1003617 | B11: SB855147537 | C11: 46 | D11: 2024-09-20 | E11: 34 | F11: KOL | G11: HYD | H11: 3A | I11: 2024-08-14 02:24:03 | J11: 3 | K11: Confirmed | L11: 7560 | M11: SYNTHETIC
A12: 1003866 | B12: SB809652026 | C12: 5 | D12: 2024-10-07 | E12: 3 | F12: DEL | G12: DIB | H12: 3A | I12: 2024-08-16 08:23:13 | J12: 1 | K12: Confirmed | L12: 3694 | M12: SYNTHETIC
A13: 1004416 | B13: SB749320576 | C13: 20 | D13: 2024-09-17 | E13: 14 | F13: IND | G13: AMR | H13: SL | I13: 2024-08-20 14:22:11 | J13: 1 | K13: Confirmed | L13: 482 | M13: SYNTHETIC
A14: 1004645 | B14: SB615109845 | C14: 3 | D14: 2024-11-19 | E14: 1 | F14: DEL | G14: MAU | H14: 2S | I14: 2024-08-22 09:48:47 | J14: 1 | K14: Confirmed | L14: 1314 | M14: SYNTHETIC
A15: 1004815 | B15: SB869189215 | C15: 20 | D15: 2024-09-17 | E15: 14 | F15: IND | G15: AMR | H15: SL | I15: 2024-08-23 08:38:50 | J15: 1 | K15: Cancelled | L15: 804 | M15: SYNTHETIC
A16: 1004847 | B16: SB811133567 | C16: 17 | D16: 2024-11-06 | E16: 11 | F16: CHA | G16: VIS | H16: 3A | I16: 2024-08-23 11:40:24 | J16: 1 | K16: Cancelled | L16: 3219 | M16: SYNTHETIC
... A33: 1009096 | B33: SB508682056 | C33: 22 | D33: 2024-10-01 | E33: 16 | F33: PUN | G33: DEH | H33: 2A | I33: 2024-09-13 02:30:31 | J33: 2 | K33: Confirmed | L33: 8022 | M33: SYNTHETIC
A34: 1010912 | B34: SB964024032 | C34: 44 | D34: 2024-09-28 | F34: KOL | G34: HYD | H34: 2S | I34: 2024-09-20 17:58:19 | J34: 1 | K34: Waitlisted | L34: 452 | M34: SYNTHETIC
A35: 1011314 | B35: SB047199954 | C35: 31 | D35: 2025-01-07 | E35: 23 | F35: MUM | G35: BEN | H35: 3A | I35: 2024-09-22 09:20:44 | J35: 1 | K35: Cancelled | L35: 1731 | M35: SYNTHETIC
A36: 1011658 | B36: SB173101738 | C36: 1 | D36: 2024-10-31 | E36: 1 | F36: DEL | G36: MAU | H36: 2S | I36: 2024-09-23 16:52:35 | J36: 4 | K36: Confirmed | M36: SYNTHETIC
A37: 1011942 | B37: SB032857862 | C37: 17 | D37: 2024-09-25 | E37: 11 | F37: CHA | G37: VIS | H37: 2S | I37: 2024-09-24 20:51:16 | J37: 1 | K37: N/A | L37: 1008 | M37: SYNTHETIC
A38: 1012042 | B38: SB476433962 | C38: 5 | D38: 2024-12-07 | F38: DEL | G38: DIB | H38: SL | I38: 2024-09-25 11:15:27 | J38: 1 | K38: Confirmed | L38: 1390 | M38: SYNTHETIC
A39: 1012374 | B39: SB749106614 | C39: 20 | D39: 2024-10-29 | E39: 14 | F39: IND | G39: AMR | H39: 3A | I39: 2024-09-26 18:45:24 | J39: 1 | K39: Cancelled | L39: 2130 | M39: SYNTHETIC
A40: 1012464 | B40: SB648325104 | C40: 44 | D40: 2024-09-28 | E40: 34 | F40: KOL | G40: HYD | H40: 3A | I40: 2024-09-27 06:39:12 | J40: 1 | K40: RAC | L40: 2402 | M40: SYNTHETIC
A41: 1012655 | B41: SB645555455 | C41: 36 | D41: 2024-10-06 | E41: 26 | F41: CHE | G41: AHM | H41: SL | I41: 2024-09-27 20:59:36 | J41: 4 | K41: Confirmed | L41: 3776 | M41: SYNTHETIC
A42: 1012794 | B42: SB612126234 | C42: 12 | D42: 2024-10-13 | E42: 8 | F42: RAI | G42: JAI | H42: 2S | I42: 2024-09-28 13:55:29 | J42: 2 | K42: Confirmed | L42: 931 | M42: SYNTHETIC
A43: 1013233 | B43: SB909425313 | C43: 31 | D43: 2024-10-15 | F43: MUM | G43: BEN | H43: SL | I43: 2024-09-30 10:03:22 | J43: 1 | K43: Cancelled | L43: 654 | M43: SYNTHETIC
A44: 1013270 | B44: SB123548470 | C44: 46 | D44: 2024-10-23 | E44: 34 | F44: KOL | G44: HYD | H44: SL | I44: 2024-09-30 13:08:00 | J44: 1 | K44: Cancelled | L44: 950 | M44: SYNTHETIC
A45: 1013494 | B45: SB717158934 | C45: 19 | D45: 2024-11-10 | E45: 13 | F45: AMR | G45: IND | H45: SL | I45: 2024-10-01 10:34:18 | J45: 3 | K45: Confirmed | L45: 2090 | M45: SYNTHETIC
A46: 1013497 | B46: SB680466217 | C46: 33 | D46: 2024-11-12 | E46: 25 | F46: AHM | G46: CHE | H46: 3A | I46: 2024-10-01 10:46:55 | J46: 2 | K46: Mixed | L46: 5568 | M46: SYNTHETIC
A47: 1013731 | B47: SB818434291 | C47: 6 | D47: 2024-11-02 | E47: 4 | F47: DIB | G47: DEL | H47: SL | I47: 2024-10-02 11:33:19 | J47: 3 | K47: Confirmed | L47: 3614 | M47: SYNTHETIC
A48: 1013942 | B48: SB904379862 | C48: 52 | D48: 2024-11-02 | E48: 40 | F48: PAT | G48: VIJ | H48: 3A | I48: 2024-10-03 09:29:38 | J48: 1 | K48: Confirmed | L48: 1358 | M48: SYNTHETIC
A49: 1014041 | B49: SB693520201 | C49: 18 | D49: 2024-10-10 | E49: 12 | F49: VIS | G49: CHA | H49: SL | I49: 2024-10-03 16:51:21 | J49: 2 | K49: Cancelled | L49: 2424 | M49: SYNTHETIC
A50: 1015068 | B50: SB799046748 | C50: 19 | D50: 2024-12-21 | E50: 13 | F50: AMR | G50: IND | H50: 2S | I50: 2024-10-07 17:21:56 | J50: 1 | K50: Confirmed | L50: 668 | M50: SYNTHETIC
A51: 1015189 | B51: SB985773829 | C51: 40 | D51: 2024-10-25 | E51: 30 | F51: THI | G51: NAG | H51: 2A | I51: 2024-10-08 07:15:28 | J51: 3 | K51: Confirmed | L51: 10355 | M51: SYNTHETIC
A52: 1015275 | B52: SB267249275 | C52: 4 | D52: 2024-12-18 | E52: 2 | F52: MAU | G52: DEL | H52: 3A | I52: 2024-10-08 12:06:25 | J52: 2 | K52: Cancelled | L52: 6297 | M52: SYNTHETIC
A53: 1015447 | B53: SB830200167 | C53: 18 | D53: 2024-10-10 | E53: 12 | F53: VIS | G53: CHA | H53: SL | I53: 2024-10-09 05:53:24 | J53: 3 | K53: Mixed | L53: 3636 | M53: SYNTHETIC
A54: 1015771 | B54: SB867386731 | C54: 18 | D54: 2025-01-29 | E54: 12 | F54: VIS | G54: CHA | H54: 3A | I54: 2024-10-10 09:13:17 | J54: 3 | K54: Confirmed | L54: 6438 | M54: SYNTHETIC
A55: 1015789 | B55: SB647230429 | C55: 12 | D55: 2024-10-13 | E55: 8 | F55: RAI | G55: JAI | H55: 3A | I55: 2024-10-10 10:13:21 | J55: 4 | K55: Confirmed | L55: 5934 | M55: SYNTHETIC
... A60: 1017303 | B60: SB462972583 | C60: 48 | D60: 2024-10-21 | E60: 36 | F60: BHU | G60: KOC | H60: 3A | I60: 2024-10-15 17:00:31 | J60: 4 | K60: Confirmed | L60: 12492 | M60: SYNTHETIC
...

Sheet Raw_Passengers
A1: passenger_id | B1: booking_id | C1: passenger_seq | D1: age_band | E1: fare_amount | F1: initial_status | G1: final_status | H1: cancellation_id | I1: data_origin
A2: 1257 | B2: 1000611 | C2: 1 | D2: Adult | E2: 1314 | F2: Confirmed | G2: Confirmed | I2: SYNTHETIC
A3: 1258 | B3: 1000611 | C3: 2 | D3: Adult | E3: 1314 | F3: Confirmed | G3: Confirmed | I3: SYNTHETIC
A4: 1259 | B4: 1000611 | C4: 3 | D4: Adult | E4: 1314 | F4: Confirmed | G4: Confirmed | I4: SYNTHETIC
A5: 1260 | B5: 1000611 | C5: 4 | D5: Senior | E5: 789 | F5: Confirmed | G5: Confirmed | I5: SYNTHETIC
A6: 3797 | B6: 1001896 | C6: 1 | D6: Adult | E6: 1053 | F6: Confirmed | G6: Confirmed | I6: SYNTHETIC
A7: 3798 | B7: 1001896 | C7: 2 | D7: Adult | E7: 1053 | F7: Confirmed | G7: Confirmed | I7: SYNTHETIC
A8: 3799 | B8: 1001896 | C8: 3 | D8: Adult | E8: 1053 | F8: Confirmed | G8: Confirmed | I8: SYNTHETIC
A9: 4015 | B9: 1002009 | C9: 1 | D9: Adult | E9: 544 | F9: Confirmed | G9: Confirmed | I9: SYNTHETIC
A10: 4016 | B10: 1002009 | C10: 2 | D10: Child | E10: 272 | F10: Confirmed | G10: Confirmed | I10: SYNTHETIC
A11: 4783 | B11: 1002389 | C11: 1 | D11: Adult | E11: 872 | F11: Confirmed | G11: Confirmed | I11: SYNTHETIC
A12: 4784 | B12: 1002389 | C12: 2 | D12: Child | E12: 436 | F12: Confirmed | G12: Confirmed | I12: SYNTHETIC
A13: 5077 | B13: 1002524 | C13: 1 | D13: Adult | E13: 2402 | F13: Confirmed | G13: Confirmed | I13: SYNTHETIC
... A29: 9483 | B29: 1004645 | C29: 1 | D29: Adult | E29: 1314 | F29: Confirmed | G29: Confirmed | I29: SYNTHETIC
A30: 9822 | B30: 1004815 | C30: 1 | D30: Adult | E30: 804 | F30: Confirmed | G30: Cancelled | H30: 776 | I30: SYNTHETIC
A31: 9892 | B31: 1004847 | C31: 1 | D31: Adult | E31: 3219 | F31: Confirmed | G31: Cancelled | H31: 2735 | I31: SYNTHETIC
A32: 10555 | B32: 1005162 | C32: 1 | D32: Adult | E32: 1854 | F32: Confirmed | G32: Confirmed | I32: SYNTHETIC
A33: 11394 | B33: 1005562 | C33: 1 | D33: Adult | E33: 870 | F33: Confirmed | G33: Confirmed | I33: SYNTHETIC
A34: 11395 | B34: 1005562 | C34: 2 | D34: Senior | E34: 522 | F34: Confirmed | G34: Confirmed | I34: SYNTHETIC
A35: 11428 | B35: 1005583 | C35: 1 | D35: Adult | E35: 1390 | F35: Confirmed | G35: Confirmed | I35: SYNTHETIC
A36: 12364 | B36: 1006037 | C36: 1 | D36: Adult | E36: 2211 | F36: Confirmed | G36: Confirmed | I36: SYNTHETIC
A37: 12365 | B37: 1006037 | C37: 2 | D37: Adult | E37: 2211 | F37: Confirmed | G37: Confirmed | I37: SYNTHETIC
A38: 12366 | B38: 1006037 | C38: 3 | D38: Adult | E38: 2211 | F38: Confirmed | G38: Confirmed | I38: SYNTHETIC
A39: 13013 | B39: 1006359 | C39: 1 | D39: Senior | E39: 393 | F39: Confirmed | G39: Cancelled | H39: 629 | I39: SYNTHETIC
A40: 13257 | B40: 1006475 | C40: 1 | D40: Adult | E40: 833 | F40: Confirmed | G40: Confirmed | I40: SYNTHETIC
A41: 13258 | B41: 1006475 | C41: 2 | D41: Adult | E41: 833 | F41: Confirmed | G41: Confirmed | I41: SYNTHETIC
A42: 13659 | B42: 1006678 | C42: 1 | D42: Adult | E42: 1176 | F42: Confirmed | G42: Confirmed | I42: SYNTHETIC
A43: 13660 | B43: 1006678 | C43: 2 | D43: Child | E43: 588 | F43: Confirmed | G43: Confirmed | I43: SYNTHETIC
A44: 13661 | B44: 1006678 | C44: 3 | D44: Child | E44: 588 | F44: Confirmed | G44: Confirmed | I44: SYNTHETIC
A45: 13662 | B45: 1006678 | C45: 4 | D45: Adult | E45: 1176 | F45: Confirmed | G45: Confirmed | I45: SYNTHETIC
A46: 13663 | B46: 1006678 | C46: 5 | D46: Adult | E46: 1176 | F46: Confirmed | G46: Confirmed | I46: SYNTHETIC
A47: 13664 | B47: 1006678 | C47: 6 | D47: Adult | E47: 1176 | F47: Confirmed | G47: Confirmed | I47: SYNTHETIC
A48: 13672 | B48: 1006682 | C48: 1 | D48: Adult | E48: 1390 | F48: Confirmed | G48: Confirmed | I48: SYNTHETIC
A49: 13673 | B49: 1006682 | C49: 2 | D49: Child | E49: 695 | F49: Confirmed | G49: Confirmed | I49: SYNTHETIC
A50: 13674 | B50: 1006682 | C50: 3 | D50: Child | E50: 695 | F50: Confirmed | G50: Confirmed | I50: SYNTHETIC
A51: 13675 | B51: 1006682 | C51: 4 | D51: Adult | E51: 1390 | F51: Confirmed | G51: Confirmed | I51: SYNTHETIC
A52: 13715 | B52: 1006706 | C52: 1 | D52: Adult | E52: 753 | F52: Confirmed | G52: #N/A | H52: 1069 | I52: SYNTHETIC
A53: 14078 | B53: 1006886 | C53: 1 | D53: Adult | E53: 2429 | F53: Confirmed | G53: Confirmed | I53: SYNTHETIC
A54: 15276 | B54: 1007455 | C54: 1 | D54: Adult | E54: 854 | F54: Confirmed | G54: Confirmed | I54: SYNTHETIC
A55: 15602 | B55: 1007632 | C55: 1 | D55: Adult | E55: 3694 | F55: Confirmed | G55: Confirmed | I55: SYNTHETIC
...

Sheet Raw_Cancellations
A1: cancellation_id | B1: booking_id | C1: cancellation_ts | D1: cancellation_type | E1: status_at_cancellation | F1: cancelled_passengers | G1: original_fare_amount | H1: cancellation_charge | I1: refund_amount | J1: data_origin
A2: 629 | B2: 1006359 | C2: 2024-09-03 23:49:58 | D2: Passenger | E2: Confirmed | F2: 1 | G2: 393 | H2: 120 | I2: 273 | J2: SYNTHETIC
A3: 776 | B3: 1004815 | C3: 2024-09-09 06:08:16 | D3: Passenger | E3: Confirmed | F3: 1 | G3: 804 | H3: 120 | I3: 684 | J3: SYNTHETIC
A4: 1069 | B4: 1006706 | C4: 2024-09-19 21:36:13 | D4: Passenger | E4: Confirmed | F4: 1 | G4: 753 | H4: 60 | I4: 693 | J4: SYNTHETIC
A5: 1514 | B5: 1010912 | C5: 2024-09-28 15:15:00 | D5: System | E5: Waitlisted | F5: 1 | G5: 452 | H5: 30 | I5: 422 | J5: SYNTHETIC
A6: 1680 | B6: 1013233 | C6: 2024-10-02 15:45:19 | D6: Passenger | E6: Confirmed | F6: 1 | G6: 654 | H6: 120 | I6: 534 | J6: SYNTHETIC
A7: 1729 | B7: 1013270 | C7: 2024-10-04 03:51:20 | D7: Passenger | E7: Confirmed | F7: 1 | G7: 950 | H7: 120 | I7: 830 | J7: SYNTHETIC
A8: 1828 | B8: 1014041 | C8: 2024-10-02 11:51:21 | D8: Passenger | E8: Confirmed | F8: 2 | G8: 2424 | H8: 240 | I8: 2184 | J8: SYNTHETIC
A9: 1950 | B9: 1015447 | C9: 2024-10-09 19:38:25 | D9: Passenger | E9: Confirmed | F9: 1 | G9: 1212 | H9: 606 | I9: 606 | J9: SYNTHETIC
A10: 2032 | B10: 1013497 | C10: 2024-10-11 19:12:36 | D10: Passenger | E10: Confirmed | F10: 1 | G10: 2784 | H10: 180 | I10: 2604 | J10: SYNTHETIC
A11: 2080 | B11: 1008844 | C11: 2024-10-12 14:59:02 | D11: Passenger | E11: Confirmed | F11: 2 | G11: 1668 | H11: 417 | I11: 1251 | J11: SYNTHETIC
A12: 2515 | B12: 1012374 | C12: 2024-10-22 01:32:31 | D12: Passenger | E12: Confirmed | F12: 1 | G12: 2130 | H12: 180 | I12: 1950 | J12: SYNTHETIC
A13: 2735 | B13: 1004847 | C13: 2024-10-25 04:32:00 | D13: Passenger | E13: Confirmed | F13: 1 | G13: 3219 | H13: 180 | I13: 3039 | J13: SYNTHETIC
... A179: 44220 | B179: 9000123 | C179: 2026-05-31 15:15:00 | D179: System | E179: Waitlisted | F179: 4 | G179: 2711 | H179: 120 | I179: 2591 | J179: SYNTHETIC

Sheet Raw_Capacity
A1: capacity_id | B1: train_id | C1: journey_date | D1: travel_class | E1: coaches_attached | F1: seats_per_coach | G1: total_seats | H1: rac_berths | I1: wl_limit | J1: data_origin
A2: 43 | B2: 25 | C2: 2024-09-24 | D2: 2A | E2: 1 | F2: 46 | G2: 46 | H2: 5 | I2: 14 | J2: SYNTHETIC
A3: 124 | B3: 2 | C3: 2024-10-23 | D3: SL | E3: 3 | F3: 72 | G3: 216 | H3: 24 | I3: 65 | J3: SYNTHETIC
A4: 135 | B4: 46 | C4: 2024-10-23 | D4: 2A | E4: 2 | F4: 46 | G4: 92 | H4: 10 | I4: 28 | J4: SYNTHETIC
A5: 139 | B5: 23 | C5: 2024-10-17 | D5: 3A | E5: 3 | F5: 64 | G5: 192 | H5: 21 | I5: 58 | J5: SYNTHETIC
A6: 141 | B6: 38 | C6: 2024-10-12 | D6: 2A | E6: 1 | F6: 46 | G6: 46 | H6: 5 | I6: 14 | J6: SYNTHETIC
A7: 149 | B7: 7 | C7: 2024-10-24 | D7: SL | E7: 2 | F7: 72 | G7: 144 | H7: 16 | I7: 43 | J7: SYNTHETIC
A8: 153 | B8: 47 | C8: 2024-10-24 | D8: 3A | E8: 2 | F8: 64 | G8: 128 | H8: 14 | I8: 38 | J8: SYNTHETIC
A9: 203 | B9: 31 | C9: 2024-11-19 | D9: 3A | E9: 2 | F9: 64 | G9: 128 | H9: 14 | I9: 38 | J9: SYNTHETIC
A10: 216 | B10: 38 | C10: 2024-11-30 | D10: 3A | E10: 3 | F10: 64 | G10: 192 | H10: 21 | I10: 58 | J10: SYNTHETIC
A11: 264 | B11: 19 | C11: 2024-11-10 | D11: SL | E11: 4 | F11: 72 | G11: 288 | H11: 32 | I11: 86 | J11: SYNTHETIC
A12: 286 | B12: 23 | C12: 2024-11-22 | D12: SL | E12: 2 | F12: 78 | G12: 144 | H12: 16 | I12: 43 | J12: SYNTHETIC
A13: 308 | B13: 49 | C13: 2024-12-10 | D13: 3A | E13: 3 | F13: 64 | G13: 192 | H13: 21 | I13: 58 | J13: SYNTHETIC
... A92: 2303 | B92: 4 | C92: 2024-12-18 | D92: 3A | E92: 3 | F92: 64 | G92: 162 | H92: 21 | I92: 58 | J92: SYNTHETIC

Sheet Raw_Operations
A1: operation_id | B1: train_id | C1: run_date | D1: departure_delay_min | E1: arrival_delay_min | F1: data_origin
A2: 12 | B2: 23 | C2: 2024-09-27 | D2: 15 | E2: 38 | F2: SYNTHETIC
A3: 17 | B3: 38 | C3: 2024-09-07 | D3: -3 | F3: SYNTHETIC
A4: 44 | B4: 5 | C4: 2024-10-07 | D4: -7 | E4: 10 | F4: SYNTHETIC
A5: 45 | B5: 13 | C5: 2024-10-27 | D5: -9 | E5: -10 | F5: SYNTHETIC
A6: 57 | B6: 27 | C6: 2024-10-24 | D6: 2 | E6: 6 | F6: SYNTHETIC
A7: 59 | B7: 36 | C7: 2024-10-06 | D7: 1 | E7: 5000 | F7: SYNTHETIC
A8: 73 | B8: 38 | C8: 2024-11-30 | D8: 2 | E8: -4 | F8: SYNTHETIC
A9: 74 | B9: 52 | C9: 2024-11-02 | D9: 15 | E9: 36 | F9: SYNTHETIC
A10: 93 | B10: 18 | C10: 2024-11-27 | D10: 2 | E10: 4 | F10: SYNTHETIC
A11: 100 | B11: 35 | C11: 2024-12-02 | D11: 0 | E11: 2 | F11: SYNTHETIC
A12: 130 | B12: 1 | C12: 2025-01-05 | D12: 41 | F12: SYNTHETIC
A13: 161 | B13: 46 | C13: 2025-02-17 | D13: 31 | E13: 51 | F13: SYNTHETIC
A14: 168 | B14: 22 | C14: 2025-02-05 | D14: -1 | E14: -7 | F14: SYNTHETIC
A15: 173 | B15: 36 | C15: 2025-02-15 | D15: 19 | E15: 59 | F15: SYNTHETIC
A16: 176 | B16: 39 | C16: 2025-02-21 | D16: -5 | E16: -12 | F16: SYNTHETIC
A17: 195 | B17: 13 | C17: 2025-03-05 | D17: -1 | E17: 2 | F17: SYNTHETIC
A18: 217 | B18: 14 | C18: 2025-03-23 | D18: 2 | F18: SYNTHETIC
A19: 230 | B19: 43 | C19: 2025-04-17 | D19: -10 | E19: -3 | F19: SYNTHETIC
A20: 242 | B20: 34 | C20: 2025-04-14 | D20: -2 | E20: 0 | F20: SYNTHETIC
A21: 248 | B21: 26 | C21: 2025-04-27 | D21: -7 | E21: -999 | F21: SYNTHETIC
A22: 260 | B22: 30 | C22: 2025-05-14 | D22: 13 | E22: 27 | F22: SYNTHETIC
A23: 289 | B23: 45 | C23: 2025-06-23 | D23: 95 | E23: 143 | F23: SYNTHETIC
A24: 299 | B24: 36 | C24: 2025-06-13 | D24: -6 | E24: -11 | F24: SYNTHETIC
A25: 313 | B25: 17 | C25: 2025-06-25 | D25: 3 | E25: 15 | F25: SYNTHETIC
A26: 321 | B26: 29 | C26: 2025-07-13 | D26: -2 | E26: -5 | F26: SYNTHETIC
A27: 328 | B27: 52 | C27: 2025-07-12 | D27: -5 | E27: -2 | F27: SYNTHETIC
A28: 344 | B28: 49 | C28: 2025-07-15 | D28: 71 | E28: 155 | F28: SYNTHETIC
A29: 364 | B29: 37 | C29: 2025-08-02 | D29: -6 | F29: SYNTHETIC
A30: 384 | B30: 36 | C30: 2025-08-12 | D30: 34 | E30: 111 | F30: SYNTHETIC
A31: 411 | B31: 27 | C31: 2025-09-13 | D31: 36 | E31: 91 | F31: SYNTHETIC
A32: 454 | B32: 20 | C32: 2025-11-11 | D32: 5 | F32: SYNTHETIC
A33: 463 | B33: 12 | C33: 2025-11-02 | D33: 21 | E33: 53 | F33: SYNTHETIC
A34: 490 | B34: 47 | C34: 2025-12-22 | D34: 70 | E34: -999 | F34: SYNTHETIC
A35: 496 | B35: 2 | C35: 2025-12-23 | D35: -5 | E35: 0 | F35: SYNTHETIC
A36: 501 | B36: 29 | C36: 2025-12-03 | D36: 20 | E36: 82 | F36: SYNTHETIC
A37: 503 | B37: 49 | C37: 2025-12-02 | D37: 1 | F37: SYNTHETIC
A38: 509 | B38: 35 | C38: 2025-12-29 | D38: -3 | E38: 9999 | F38: SYNTHETIC
A39: 551 | B39: 9 | C39: 2026-02-20 | D39: 0 | E39: 4 | F39: SYNTHETIC
A40: 556 | B40: 1 | C40: 2026-02-26 | D40: -1 | E40: -1 | F40: SYNTHETIC
...

Sheet Work_Bookings
A1: id | B1: dup | C1: jd_text | D1: pat | E1: y | F1: m | G1: d | H1: valid | I1: jd_clean | J1: f_date_format (flag) | K1: f_date_impossible (flag) | L1: ts_missing | M1: ts_value | N1: f_after (flag) | O1: board_norm | P1: dest_norm | Q1: board_known | R1: dest_known | S1: f_station_format (flag) | T1: f_station_unknown (flag) | U1: f_route_missing (flag) | V1: status_norm | W1: f_status_alias (flag) | X1: f_status_invalid (flag) | Y1: f_total_missing (flag) | Z1: total_is_text | AA1: total_parsed | AB1: f_total_currency (flag) | AC1: f_numpax_invalid (flag) | AE1: SYNTHETIC DATA (defect-enriched sample of the raw extract). Not real data.
A2: =Raw_Bookings!A2 -> 1000611 | B2: =IF(COUNTIF(Raw_Bookings!$A$2:A2,Raw_Bookings!A2)>1,1,0) -> 0 | C2: =Raw_Bookings!D2&"" -> 2024-09-04 | D2: =IF(AND(LEN(C2)=10,MID(C2,5,1)="-",MID(C2,8,1)="-"),"ISO",IF(AND(LEN(C2)=10,MID(C2,3,1)="-",MID(C2,6,1)="-"),"DMY","OTHER")) -> ISO | E2: =IF(D2="ISO",VALUE(LEFT(C2,4)),IF(D2="DMY",VALUE(RIGHT(C2,4)),0)) -> 2024 | F2: =IF(D2="ISO",VALUE(MID(C2,6,2)),IF(D2="DMY",VALUE(MID(C2,4,2)),0)) -> 9 | G2: =IF(D2="ISO",VALUE(RIGHT(C2,2)),IF(D2="DMY",VALUE(LEFT(C2,2)),0)) -> 4 | H2: =IF(AND(D2<>"OTHER",F2>=1,F2<=12,G2>=1,G2<=31),IF(AND(MONTH(DATE(E2,F2,G2))=F2,DAY(DATE(E2,F2,G2))=G2),1,0),0) -> 1 | I2: =IF(H2=1,DATE(E2,F2,G2),"") -> 45539 | J2: =IF(AND(D2="DMY",H2=1),1,0) -> 0 | K2: =IF(H2=0,1,0) -> 0 | L2: =IF(TRIM(Raw_Bookings!I2&"")="",1,0) -> 0 | M2: =IF(L2=1,"",DATEVALUE(LEFT(Raw_Bookings!I2,10))+TIMEVALUE(MID(Raw_Bookings!I2,12,8))) -> 45470.842 | N2: =IF(AND(L2=0,H2=1),IF(INT(M2)>I2,1,0),0) -> 0 | O2: =UPPER(TRIM(Raw_Bookings!F2)) -> MAU | P2: =UPPER(TRIM(Raw_Bookings!G2)) -> DEL | Q2: =IF(COUNTIF(Lookup_Stations!$A$2:$A$33,O2)>0,1,0) -> 1 | R2: =IF(COUNTIF(Lookup_Stations!$A$2:$A$33,P2)>0,1,0) -> 1 | S2: =IF(OR(AND(Q2=1,NOT(EXACT(Raw_Bookings!F2,O2))),AND(R2=1,NOT(EXACT(Raw_Bookings!G2,P2)))),1,0) -> 0 | T2: =IF(OR(Q2=0,R2=0),1,0) -> 0 | U2: =IF(TRIM(Raw_Bookings!E2&"")="",1,0) -> 0 | V2: =IF(SUMPRODUCT(--(Lookup_Status!$A$2:$A$13=LOWER(TRIM(Raw_Bookings!K2))))=0,"",INDEX(Lookup_Status!$B$2:$B$13,SUMPRODUCT((Lookup_Status!$A$2:$A$13=LOWER(TRIM(Raw_Bookings!K2)))*(ROW(Lookup_Status!$A$2:$A$13)-1)))) -> Confirmed | W2: =IF(AND(V2<>"",NOT(EXACT(Raw_Bookings!K2,V2))),1,0) -> 0 | X2: =IF(V2="",1,0) -> 0 | Y2: =IF(TRIM(Raw_Bookings!L2&"")="",1,0) -> 0 | Z2: =IF(AND(ISTEXT(Raw_Bookings!L2),Y2=0),1,0) -> 0 | AA2: =IF(Z2=1,IFERROR(VALUE(SUBSTITUTE(SUBSTITUTE(SUBSTITUTE(SUBSTITUTE(SUBSTITUTE(UPPER(Raw_Bookings!L2),"RS.",""),"₹",""),",","")," ",""),"INR","")),""),"") | AB2: =IF(AND(Z2=1,ISNUMBER(AA2)),1,0) -> 0 | AC2: =IF(B2=1,0,IF(NOT(ISNUMBER(Raw_Bookings!J2)),1,IF(Raw_Bookings!J2<>COUNTIFS(Work_Passengers!$B$2:$B$1336,Raw_Bookings!A2,Work_Passengers!$C$2:$C$1336,0),1,0))) -> 0
A3: =Raw_Bookings!A3 -> 1001896 | B3: =IF(COUNTIF(Raw_Bookings!$A$2:A3,Raw_Bookings!A3)>1,1,0) -> 0 | C3: =Raw_Bookings!D3&"" -> 2024-09-16 | D3: =IF(AND(LEN(C3)=10,MID(C3,5,1)="-",MID(C3,8,1)="-"),"ISO",IF(AND(LEN(C3)=10,MID(C3,3,1)="-",MID(C3,6,1)="-"),"DMY","OTHER")) -> ISO | E3: =IF(D3="ISO",VALUE(LEFT(C3,4)),IF(D3="DMY",VALUE(RIGHT(C3,4)),0)) -> 2024 | F3: =IF(D3="ISO",VALUE(MID(C3,6,2)),IF(D3="DMY",VALUE(MID(C3,4,2)),0)) -> 9 | G3: =IF(D3="ISO",VALUE(RIGHT(C3,2)),IF(D3="DMY",VALUE(LEFT(C3,2)),0)) -> 16 | H3: =IF(AND(D3<>"OTHER",F3>=1,F3<=12,G3>=1,G3<=31),IF(AND(MONTH(DATE(E3,F3,G3))=F3,DAY(DATE(E3,F3,G3))=G3),1,0),0) -> 1 | I3: =IF(H3=1,DATE(E3,F3,G3),"") -> 45551 | J3: =IF(AND(D3="DMY",H3=1),1,0) -> 0 | K3: =IF(H3=0,1,0) -> 0 | L3: =IF(TRIM(Raw_Bookings!I3&"")="",1,0) -> 0 | M3: =IF(L3=1,"",DATEVALUE(LEFT(Raw_Bookings!I3,10))+TIMEVALUE(MID(Raw_Bookings!I3,12,8))) -> 45499.658 | N3: =IF(AND(L3=0,H3=1),IF(INT(M3)>I3,1,0),0) -> 0 | O3: =UPPER(TRIM(Raw_Bookings!F3)) -> DEH | P3: =UPPER(TRIM(Raw_Bookings!G3)) -> PUN | Q3: =IF(COUNTIF(Lookup_Stations!$A$2:$A$33,O3)>0,1,0) -> 1 | R3: =IF(COUNTIF(Lookup_Stations!$A$2:$A$33,P3)>0,1,0) -> 1 | S3: =IF(OR(AND(Q3=1,NOT(EXACT(Raw_Bookings!F3,O3))),AND(R3=1,NOT(EXACT(Raw_Bookings!G3,P3)))),1,0) -> 0 | T3: =IF(OR(Q3=0,R3=0),1,0) -> 0 | U3: =IF(TRIM(Raw_Bookings!E3&"")="",1,0) -> 0 | V3: =IF(SUMPRODUCT(--(Lookup_Status!$A$2:$A$13=LOWER(TRIM(Raw_Bookings!K3))))=0,"",INDEX(Lookup_Status!$B$2:$B$13,SUMPRODUCT((Lookup_Status!$A$2:$A$13=LOWER(TRIM(Raw_Bookings!K3)))*(ROW(Lookup_Status!$A$2:$A$13)-1)))) -> Confirmed | W3: =IF(AND(V3<>"",NOT(EXACT(Raw_Bookings!K3,V3))),1,0) -> 0 | X3: =IF(V3="",1,0) -> 0 | Y3: =IF(TRIM(Raw_Bookings!L3&"")="",1,0) -> 0 | Z3: =IF(AND(ISTEXT(Raw_Bookings!L3),Y3=0),1,0) -> 0 | AA3: =IF(Z3=1,IFERROR(VALUE(SUBSTITUTE(SUBSTITUTE(SUBSTITUTE(SUBSTITUTE(SUBSTITUTE(UPPER(Raw_Bookings!L3),"RS.",""),"₹",""),",","")," ",""),"INR","")),""),"") | AB3: =IF(AND(Z3=1,ISNUMBER(AA3)),1,0) -> 0 | AC3: =IF(B3=1,0,IF(NOT(ISNUMBER(Raw_Bookings!J3)),1,IF(Raw_Bookings!J3<>COUNTIFS(Work_Passengers!$B$2:$B$1336,Raw_Bookings!A3,Work_Passengers!$C$2:$C$1336,0),1,0))) -> 0
A4: =Raw_Bookings!A4 -> 1002009 | B4: =IF(COUNTIF(Raw_Bookings!$A$2:A4,Raw_Bookings!A4)>1,1,0) -> 0 | C4: =Raw_Bookings!D4&"" -> 2024-10-15 | D4: =IF(AND(LEN(C4)=10,MID(C4,5,1)="-",MID(C4,8,1)="-"),"ISO",IF(AND(LEN(C4)=10,MID(C4,3,1)="-",MID(C4,6,1)="-"),"DMY","OTHER")) -> ISO | E4: =IF(D4="ISO",VALUE(LEFT(C4,4)),IF(D4="DMY",VALUE(RIGHT(C4,4)),0)) -> 2024 | F4: =IF(D4="ISO",VALUE(MID(C4,6,2)),IF(D4="DMY",VALUE(MID(C4,4,2)),0)) -> 10 | G4: =IF(D4="ISO",VALUE(RIGHT(C4,2)),IF(D4="DMY",VALUE(LEFT(C4,2)),0)) -> 15 | H4: =IF(AND(D4<>"OTHER",F4>=1,F4<=12,G4>=1,G4<=31),IF(AND(MONTH(DATE(E4,F4,G4))=F4,DAY(DATE(E4,F4,G4))=G4),1,0),0) -> 1 | I4: =IF(H4=1,DATE(E4,F4,G4),"") -> 45580 | J4: =IF(AND(D4="DMY",H4=1),1,0) -> 0 | K4: =IF(H4=0,1,0) -> 0 | L4: =IF(TRIM(Raw_Bookings!I4&"")="",1,0) -> 0 | M4: =IF(L4=1,"",DATEVALUE(LEFT(Raw_Bookings!I4,10))+TIMEVALUE(MID(Raw_Bookings!I4,12,8))) -> 45501.393 | N4: =IF(AND(L4=0,H4=1),IF(INT(M4)>I4,1,0),0) -> 0 | O4: =UPPER(TRIM(Raw_Bookings!F4)) -> MUM | P4: =UPPER(TRIM(Raw_Bookings!G4)) -> BEN | Q4: =IF(COUNTIF(Lookup_Stations!$A$2:$A$33,O4)>0,1,0) -> 1 | R4: =IF(COUNTIF(Lookup_Stations!$A$2:$A$33,P4)>0,1,0) -> 1 | S4: =IF(OR(AND(Q4=1,NOT(EXACT(Raw_Bookings!F4,O4))),AND(R4=1,NOT(EXACT(Raw_Bookings!G4,P4)))),1,0) -> 0 | T4: =IF(OR(Q4=0,R4=0),1,0) -> 0 | U4: =IF(TRIM(Raw_Bookings!E4&"")="",1,0) -> 1 | V4: =IF(SUMPRODUCT(--(Lookup_Status!$A$2:$A$13=LOWER(TRIM(Raw_Bookings!K4))))=0,"",INDEX(Lookup_Status!$B$2:$B$13,SUMPRODUCT((Lookup_Status!$A$2:$A$13=LOWER(TRIM(Raw_Bookings!K4)))*(ROW(Lookup_Status!$A$2:$A$13)-1)))) -> Confirmed | W4: =IF(AND(V4<>"",NOT(EXACT(Raw_Bookings!K4,V4))),1,0) -> 0 | X4: =IF(V4="",1,0) -> 0 | Y4: =IF(TRIM(Raw_Bookings!L4&"")="",1,0) -> 0 | Z4: =IF(AND(ISTEXT(Raw_Bookings!L4),Y4=0),1,0) -> 0 | AA4: =IF(Z4=1,IFERROR(VALUE(SUBSTITUTE(SUBSTITUTE(SUBSTITUTE(SUBSTITUTE(SUBSTITUTE(UPPER(Raw_Bookings!L4),"RS.",""),"₹",""),",","")," ",""),"INR","")),""),"") | AB4: =IF(AND(Z4=1,ISNUMBER(AA4)),1,0) -> 0 | AC4: =IF(B4=1,0,IF(NOT(ISNUMBER(Raw_Bookings!J4)),1,IF(Raw_Bookings!J4<>COUNTIFS(Work_Passengers!$B$2:$B$1336,Raw_Bookings!A4,Work_Passengers!$C$2:$C$1336,0),1,0))) -> 0
A5: =Raw_Bookings!A5 -> 1002389 | B5: =IF(COUNTIF(Raw_Bookings!$A$2:A5,Raw_Bookings!A5)>1,1,0) -> 0 | C5: =Raw_Bookings!D5&"" -> 2024-11-12 | D5: =IF(AND(LEN(C5)=10,MID(C5,5,1)="-",MID(C5,8,1)="-"),"ISO",IF(AND(LEN(C5)=10,MID(C5,3,1)="-",MID(C5,6,1)="-"),"DMY","OTHER")) -> ISO | E5: =IF(D5="ISO",VALUE(LEFT(C5,4)),IF(D5="DMY",VALUE(RIGHT(C5,4)),0)) -> 2024 | F5: =IF(D5="ISO",VALUE(MID(C5,6,2)),IF(D5="DMY",VALUE(MID(C5,4,2)),0)) -> 11 | G5: =IF(D5="ISO",VALUE(RIGHT(C5,2)),IF(D5="DMY",VALUE(LEFT(C5,2)),0)) -> 12 | H5: =IF(AND(D5<>"OTHER",F5>=1,F5<=12,G5>=1,G5<=31),IF(AND(MONTH(DATE(E5,F5,G5))=F5,DAY(DATE(E5,F5,G5))=G5),1,0),0) -> 1 | I5: =IF(H5=1,DATE(E5,F5,G5),"") -> 45608 | J5: =IF(AND(D5="DMY",H5=1),1,0) -> 0 | K5: =IF(H5=0,1,0) -> 0 | L5: =IF(TRIM(Raw_Bookings!I5&"")="",1,0) -> 0 | M5: =IF(L5=1,"",DATEVALUE(LEFT(Raw_Bookings!I5,10))+TIMEVALUE(MID(Raw_Bookings!I5,12,8))) -> 45506.344 | N5: =IF(AND(L5=0,H5=1),IF(INT(M5)>I5,1,0),0) -> 0 | O5: =UPPER(TRIM(Raw_Bookings!F5)) -> AHM | P5: =UPPER(TRIM(Raw_Bookings!G5)) -> CHE | Q5: =IF(COUNTIF(Lookup_Stations!$A$2:$A$33,O5)>0,1,0) -> 1 | R5: =IF(COUNTIF(Lookup_Stations!$A$2:$A$33,P5)>0,1,0) -> 1 | S5: =IF(OR(AND(Q5=1,NOT(EXACT(Raw_Bookings!F5,O5))),AND(R5=1,NOT(EXACT(Raw_Bookings!G5,P5)))),1,0) -> 0 | T5: =IF(OR(Q5=0,R5=0),1,0) -> 0 | U5: =IF(TRIM(Raw_Bookings!E5&"")="",1,0) -> 0 | V5: =IF(SUMPRODUCT(--(Lookup_Status!$A$2:$A$13=LOWER(TRIM(Raw_Bookings!K5))))=0,"",INDEX(Lookup_Status!$B$2:$B$13,SUMPRODUCT((Lookup_Status!$A$2:$A$13=LOWER(TRIM(Raw_Bookings!K5)))*(ROW(Lookup_Status!$A$2:$A$13)-1)))) -> Confirmed | W5: =IF(AND(V5<>"",NOT(EXACT(Raw_Bookings!K5,V5))),1,0) -> 0 | X5: =IF(V5="",1,0) -> 0 | Y5: =IF(TRIM(Raw_Bookings!L5&"")="",1,0) -> 0 | Z5: =IF(AND(ISTEXT(Raw_Bookings!L5),Y5=0),1,0) -> 0 | AA5: =IF(Z5=1,IFERROR(VALUE(SUBSTITUTE(SUBSTITUTE(SUBSTITUTE(SUBSTITUTE(SUBSTITUTE(UPPER(Raw_Bookings!L5),"RS.",""),"₹",""),",","")," ",""),"INR","")),""),"") | AB5: =IF(AND(Z5=1,ISNUMBER(AA5)),1,0) -> 0 | AC5: =IF(B5=1,0,IF(NOT(ISNUMBER(Raw_Bookings!J5)),1,IF(Raw_Bookings!J5<>COUNTIFS(Work_Passengers!$B$2:$B$1336,Raw_Bookings!A5,Work_Passengers!$C$2:$C$1336,0),1,0))) -> 0
A6: =Raw_Bookings!A6 -> 1002524 | B6: =IF(COUNTIF(Raw_Bookings!$A$2:A6,Raw_Bookings!A6)>1,1,0) -> 0 | C6: =Raw_Bookings!D6&"" -> 2024-09-28 | D6: =IF(AND(LEN(C6)=10,MID(C6,5,1)="-",MID(C6,8,1)="-"),"ISO",IF(AND(LEN(C6)=10,MID(C6,3,1)="-",MID(C6,6,1)="-"),"DMY","OTHER")) -> ISO | E6: =IF(D6="ISO",VALUE(LEFT(C6,4)),IF(D6="DMY",VALUE(RIGHT(C6,4)),0)) -> 2024 | F6: =IF(D6="ISO",VALUE(MID(C6,6,2)),IF(D6="DMY",VALUE(MID(C6,4,2)),0)) -> 9 | G6: =IF(D6="ISO",VALUE(RIGHT(C6,2)),IF(D6="DMY",VALUE(LEFT(C6,2)),0)) -> 28 | H6: =IF(AND(D6<>"OTHER",F6>=1,F6<=12,G6>=1,G6<=31),IF(AND(MONTH(DATE(E6,F6,G6))=F6,DAY(DATE(E6,F6,G6))=G6),1,0),0) -> 1 | I6: =IF(H6=1,DATE(E6,F6,G6),"") -> 45563 | J6: =IF(AND(D6="DMY",H6=1),1,0) -> 0 | K6: =IF(H6=0,1,0) -> 0 | L6: =IF(TRIM(Raw_Bookings!I6&"")="",1,0) -> 0 | M6: =IF(L6=1,"",DATEVALUE(LEFT(Raw_Bookings!I6,10))+TIMEVALUE(MID(Raw_Bookings!I6,12,8))) -> 45507.522 | N6: =IF(AND(L6=0,H6=1),IF(INT(M6)>I6,1,0),0) -> 0 | O6: =UPPER(TRIM(Raw_Bookings!F6)) -> KOL | P6: =UPPER(TRIM(Raw_Bookings!G6)) -> HYD | Q6: =IF(COUNTIF(Lookup_Stations!$A$2:$A$33,O6)>0,1,0) -> 1 | R6: =IF(COUNTIF(Lookup_Stations!$A$2:$A$33,P6)>0,1,0) -> 1 | S6: =IF(OR(AND(Q6=1,NOT(EXACT(Raw_Bookings!F6,O6))),AND(R6=1,NOT(EXACT(Raw_Bookings!G6,P6)))),1,0) -> 0 | T6: =IF(OR(Q6=0,R6=0),1,0) -> 0 | U6: =IF(TRIM(Raw_Bookings!E6&"")="",1,0) -> 0 | V6: =IF(SUMPRODUCT(--(Lookup_Status!$A$2:$A$13=LOWER(TRIM(Raw_Bookings!K6))))=0,"",INDEX(Lookup_Status!$B$2:$B$13,SUMPRODUCT((Lookup_Status!$A$2:$A$13=LOWER(TRIM(Raw_Bookings!K6)))*(ROW(Lookup_Status!$A$2:$A$13)-1)))) -> Confirmed | W6: =IF(AND(V6<>"",NOT(EXACT(Raw_Bookings!K6,V6))),1,0) -> 0 | X6: =IF(V6="",1,0) -> 0 | Y6: =IF(TRIM(Raw_Bookings!L6&"")="",1,0) -> 0 | Z6: =IF(AND(ISTEXT(Raw_Bookings!L6),Y6=0),1,0) -> 0 | AA6: =IF(Z6=1,IFERROR(VALUE(SUBSTITUTE(SUBSTITUTE(SUBSTITUTE(SUBSTITUTE(SUBSTITUTE(UPPER(Raw_Bookings!L6),"RS.",""),"₹",""),",","")," ",""),"INR","")),""),"") | AB6: =IF(AND(Z6=1,ISNUMBER(AA6)),1,0) -> 0 | AC6: =IF(B6=1,0,IF(NOT(ISNUMBER(Raw_Bookings!J6)),1,IF(Raw_Bookings!J6<>COUNTIFS(Work_Passengers!$B$2:$B$1336,Raw_Bookings!A6,Work_Passengers!$C$2:$C$1336,0),1,0))) -> 0
A7: =Raw_Bookings!A7 -> 1002921 | B7: =IF(COUNTIF(Raw_Bookings!$A$2:A7,Raw_Bookings!A7)>1,1,0) -> 0 | C7: =Raw_Bookings!D7&"" -> 2024-10-13 | D7: =IF(AND(LEN(C7)=10,MID(C7,5,1)="-",MID(C7,8,1)="-"),"ISO",IF(AND(LEN(C7)=10,MID(C7,3,1)="-",MID(C7,6,1)="-"),"DMY","OTHER")) -> ISO | E7: =IF(D7="ISO",VALUE(LEFT(C7,4)),IF(D7="DMY",VALUE(RIGHT(C7,4)),0)) -> 2024 | F7: =IF(D7="ISO",VALUE(MID(C7,6,2)),IF(D7="DMY",VALUE(MID(C7,4,2)),0)) -> 10 | G7: =IF(D7="ISO",VALUE(RIGHT(C7,2)),IF(D7="DMY",VALUE(LEFT(C7,2)),0)) -> 13 | H7: =IF(AND(D7<>"OTHER",F7>=1,F7<=12,G7>=1,G7<=31),IF(AND(MONTH(DATE(E7,F7,G7))=F7,DAY(DATE(E7,F7,G7))=G7),1,0),0) -> 1 | I7: =IF(H7=1,DATE(E7,F7,G7),"") -> 45578 | J7: =IF(AND(D7="DMY",H7=1),1,0) -> 0 | K7: =IF(H7=0,1,0) -> 0 | L7: =IF(TRIM(Raw_Bookings!I7&"")="",1,0) -> 0 | M7: =IF(L7=1,"",DATEVALUE(LEFT(Raw_Bookings!I7,10))+TIMEVALUE(MID(Raw_Bookings!I7,12,8))) -> 45511.788 | N7: =IF(AND(L7=0,H7=1),IF(INT(M7)>I7,1,0),0) -> 0 | O7: =UPPER(TRIM(Raw_Bookings!F7)) -> RAI | P7: =UPPER(TRIM(Raw_Bookings!G7)) -> JAI | Q7: =IF(COUNTIF(Lookup_Stations!$A$2:$A$33,O7)>0,1,0) -> 1 | R7: =IF(COUNTIF(Lookup_Stations!$A$2:$A$33,P7)>0,1,0) -> 1 | S7: =IF(OR(AND(Q7=1,NOT(EXACT(Raw_Bookings!F7,O7))),AND(R7=1,NOT(EXACT(Raw_Bookings!G7,P7)))),1,0) -> 0 | T7: =IF(OR(Q7=0,R7=0),1,0) -> 0 | U7: =IF(TRIM(Raw_Bookings!E7&"")="",1,0) -> 0 | V7: =IF(SUMPRODUCT(--(Lookup_Status!$A$2:$A$13=LOWER(TRIM(Raw_Bookings!K7))))=0,"",INDEX(Lookup_Status!$B$2:$B$13,SUMPRODUCT((Lookup_Status!$A$2:$A$13=LOWER(TRIM(Raw_Bookings!K7)))*(ROW(Lookup_Status!$A$2:$A$13)-1)))) -> Confirmed | W7: =IF(AND(V7<>"",NOT(EXACT(Raw_Bookings!K7,V7))),1,0) -> 0 | X7: =IF(V7="",1,0) -> 0 | Y7: =IF(TRIM(Raw_Bookings!L7&"")="",1,0) -> 0 | Z7: =IF(AND(ISTEXT(Raw_Bookings!L7),Y7=0),1,0) -> 0 | AA7: =IF(Z7=1,IFERROR(VALUE(SUBSTITUTE(SUBSTITUTE(SUBSTITUTE(SUBSTITUTE(SUBSTITUTE(UPPER(Raw_Bookings!L7),"RS.",""),"₹",""),",","")," ",""),"INR","")),""),"") | AB7: =IF(AND(Z7=1,ISNUMBER(AA7)),1,0) -> 0 | AC7: =IF(B7=1,0,IF(NOT(ISNUMBER(Raw_Bookings!J7)),1,IF(Raw_Bookings!J7<>COUNTIFS(Work_Passengers!$B$2:$B$1336,Raw_Bookings!A7,Work_Passengers!$C$2:$C$1336,0),1,0))) -> 0
A8: =Raw_Bookings!A8 -> 1002990 | B8: =IF(COUNTIF(Raw_Bookings!$A$2:A8,Raw_Bookings!A8)>1,1,0) -> 0 | C8: =Raw_Bookings!D8&"" -> 2024-10-06 | D8: =IF(AND(LEN(C8)=10,MID(C8,5,1)="-",MID(C8,8,1)="-"),"ISO",IF(AND(LEN(C8)=10,MID(C8,3,1)="-",MID(C8,6,1)="-"),"DMY","OTHER")) -> ISO | E8: =IF(D8="ISO",VALUE(LEFT(C8,4)),IF(D8="DMY",VALUE(RIGHT(C8,4)),0)) -> 2024 | F8: =IF(D8="ISO",VALUE(MID(C8,6,2)),IF(D8="DMY",VALUE(MID(C8,4,2)),0)) -> 10 | G8: =IF(D8="ISO",VALUE(RIGHT(C8,2)),IF(D8="DMY",VALUE(LEFT(C8,2)),0)) -> 6 | H8: =IF(AND(D8<>"OTHER",F8>=1,F8<=12,G8>=1,G8<=31),IF(AND(MONTH(DATE(E8,F8,G8))=F8,DAY(DATE(E8,F8,G8))=G8),1,0),0) -> 1 | I8: =IF(H8=1,DATE(E8,F8,G8),"") -> 45571 | J8: =IF(AND(D8="DMY",H8=1),1,0) -> 0 | K8: =IF(H8=0,1,0) -> 0 | L8: =IF(TRIM(Raw_Bookings!I8&"")="",1,0) -> 0 | M8: =IF(L8=1,"",DATEVALUE(LEFT(Raw_Bookings!I8,10))+TIMEVALUE(MID(Raw_Bookings!I8,12,8))) -> 45512.518 | N8: =IF(AND(L8=0,H8=1),IF(INT(M8)>I8,1,0),0) -> 0 | O8: =UPPER(TRIM(Raw_Bookings!F8)) -> CHE | P8: =UPPER(TRIM(Raw_Bookings!G8)) -> AHM | Q8: =IF(COUNTIF(Lookup_Stations!$A$2:$A$33,O8)>0,1,0) -> 1 | R8: =IF(COUNTIF(Lookup_Stations!$A$2:$A$33,P8)>0,1,0) -> 1 | S8: =IF(OR(AND(Q8=1,NOT(EXACT(Raw_Bookings!F8,O8))),AND(R8=1,NOT(EXACT(Raw_Bookings!G8,P8)))),1,0) -> 0 | T8: =IF(OR(Q8=0,R8=0),1,0) -> 0 | U8: =IF(TRIM(Raw_Bookings!E8&"")="",1,0) -> 0 | V8: =IF(SUMPRODUCT(--(Lookup_Status!$A$2:$A$13=LOWER(TRIM(Raw_Bookings!K8))))=0,"",INDEX(Lookup_Status!$B$2:$B$13,SUMPRODUCT((Lookup_Status!$A$2:$A$13=LOWER(TRIM(Raw_Bookings!K8)))*(ROW(Lookup_Status!$A$2:$A$13)-1)))) -> Confirmed | W8: =IF(AND(V8<>"",NOT(EXACT(Raw_Bookings!K8,V8))),1,0) -> 0 | X8: =IF(V8="",1,0) -> 0 | Y8: =IF(TRIM(Raw_Bookings!L8&"")="",1,0) -> 0 | Z8: =IF(AND(ISTEXT(Raw_Bookings!L8),Y8=0),1,0) -> 0 | AA8: =IF(Z8=1,IFERROR(VALUE(SUBSTITUTE(SUBSTITUTE(SUBSTITUTE(SUBSTITUTE(SUBSTITUTE(UPPER(Raw_Bookings!L8),"RS.",""),"₹",""),",","")," ",""),"INR","")),""),"") | AB8: =IF(AND(Z8=1,ISNUMBER(AA8)),1,0) -> 0 | AC8: =IF(B8=1,0,IF(NOT(ISNUMBER(Raw_Bookings!J8)),1,IF(Raw_Bookings!J8<>COUNTIFS(Work_Passengers!$B$2:$B$1336,Raw_Bookings!A8,Work_Passengers!$C$2:$C$1336,0),1,0))) -> 0
A9: =Raw_Bookings!A9 -> 1003061 | B9: =IF(COUNTIF(Raw_Bookings!$A$2:A9,Raw_Bookings!A9)>1,1,0) -> 0 | C9: =Raw_Bookings!D9&"" -> 2024-12-04 | D9: =IF(AND(LEN(C9)=10,MID(C9,5,1)="-",MID(C9,8,1)="-"),"ISO",IF(AND(LEN(C9)=10,MID(C9,3,1)="-",MID(C9,6,1)="-"),"DMY","OTHER")) -> ISO | E9: =IF(D9="ISO",VALUE(LEFT(C9,4)),IF(D9="DMY",VALUE(RIGHT(C9,4)),0)) -> 2024 | F9: =IF(D9="ISO",VALUE(MID(C9,6,2)),IF(D9="DMY",VALUE(MID(C9,4,2)),0)) -> 12 | G9: =IF(D9="ISO",VALUE(RIGHT(C9,2)),IF(D9="DMY",VALUE(LEFT(C9,2)),0)) -> 4 | H9: =IF(AND(D9<>"OTHER",F9>=1,F9<=12,G9>=1,G9<=31),IF(AND(MONTH(DATE(E9,F9,G9))=F9,DAY(DATE(E9,F9,G9))=G9),1,0),0) -> 1 | I9: =IF(H9=1,DATE(E9,F9,G9),"") -> 45630 | J9: =IF(AND(D9="DMY",H9=1),1,0) -> 0 | K9: =IF(H9=0,1,0) -> 0 | L9: =IF(TRIM(Raw_Bookings!I9&"")="",1,0) -> 0 | M9: =IF(L9=1,"",DATEVALUE(LEFT(Raw_Bookings!I9,10))+TIMEVALUE(MID(Raw_Bookings!I9,12,8))) -> 45513.324 | N9: =IF(AND(L9=0,H9=1),IF(INT(M9)>I9,1,0),0) -> 0 | O9: =UPPER(TRIM(Raw_Bookings!F9)) -> BEN | P9: =UPPER(TRIM(Raw_Bookings!G9)) -> MUM | Q9: =IF(COUNTIF(Lookup_Stations!$A$2:$A$33,O9)>0,1,0) -> 1 | R9: =IF(COUNTIF(Lookup_Stations!$A$2:$A$33,P9)>0,1,0) -> 1 | S9: =IF(OR(AND(Q9=1,NOT(EXACT(Raw_Bookings!F9,O9))),AND(R9=1,NOT(EXACT(Raw_Bookings!G9,P9)))),1,0) -> 0 | T9: =IF(OR(Q9=0,R9=0),1,0) -> 0 | U9: =IF(TRIM(Raw_Bookings!E9&"")="",1,0) -> 0 | V9: =IF(SUMPRODUCT(--(Lookup_Status!$A$2:$A$13=LOWER(TRIM(Raw_Bookings!K9))))=0,"",INDEX(Lookup_Status!$B$2:$B$13,SUMPRODUCT((Lookup_Status!$A$2:$A$13=LOWER(TRIM(Raw_Bookings!K9)))*(ROW(Lookup_Status!$A$2:$A$13)-1)))) -> Confirmed | W9: =IF(AND(V9<>"",NOT(EXACT(Raw_Bookings!K9,V9))),1,0) -> 0 | X9: =IF(V9="",1,0) -> 0 | Y9: =IF(TRIM(Raw_Bookings!L9&"")="",1,0) -> 0 | Z9: =IF(AND(ISTEXT(Raw_Bookings!L9),Y9=0),1,0) -> 0 | AA9: =IF(Z9=1,IFERROR(VALUE(SUBSTITUTE(SUBSTITUTE(SUBSTITUTE(SUBSTITUTE(SUBSTITUTE(UPPER(Raw_Bookings!L9),"RS.",""),"₹",""),",","")," ",""),"INR","")),""),"") | AB9: =IF(AND(Z9=1,ISNUMBER(AA9)),1,0) -> 0 | AC9: =IF(B9=1,0,IF(NOT(ISNUMBER(Raw_Bookings!J9)),1,IF(Raw_Bookings!J9<>COUNTIFS(Work_Passengers!$B$2:$B$1336,Raw_Bookings!A9,Work_Passengers!$C$2:$C$1336,0),1,0))) -> 0
A10: =Raw_Bookings!A10 -> 1003110 | B10: =IF(COUNTIF(Raw_Bookings!$A$2:A10,Raw_Bookings!A10)>1,1,0) -> 0 | C10: =Raw_Bookings!D10&"" -> 2024-09-04 | D10: =IF(AND(LEN(C10)=10,MID(C10,5,1)="-",MID(C10,8,1)="-"),"ISO",IF(AND(LEN(C10)=10,MID(C10,3,1)="-",MID(C10,6,1)="-"),"DMY","OTHER")) -> ISO | E10: =IF(D10="ISO",VALUE(LEFT(C10,4)),IF(D10="DMY",VALUE(RIGHT(C10,4)),0)) -> 2024 | F10: =IF(D10="ISO",VALUE(MID(C10,6,2)),IF(D10="DMY",VALUE(MID(C10,4,2)),0)) -> 9 | G10: =IF(D10="ISO",VALUE(RIGHT(C10,2)),IF(D10="DMY",VALUE(LEFT(C10,2)),0)) -> 4 | H10: =IF(AND(D10<>"OTHER",F10>=1,F10<=12,G10>=1,G10<=31),IF(AND(MONTH(DATE(E10,F10,G10))=F10,DAY(DATE(E10,F10,G10))=G10),1,0),0) -> 1 | I10: =IF(H10=1,DATE(E10,F10,G10),"") -> 45539 | J10: =IF(AND(D10="DMY",H10=1),1,0) -> 0 | K10: =IF(H10=0,1,0) -> 0 | L10: =IF(TRIM(Raw_Bookings!I10&"")="",1,0) -> 0 | M10: =IF(L10=1,"",DATEVALUE(LEFT(Raw_Bookings!I10,10))+TIMEVALUE(MID(Raw_Bookings!I10,12,8))) -> 45513.625 | N10: =IF(AND(L10=0,H10=1),IF(INT(M10)>I10,1,0),0) -> 0 | O10: =UPPER(TRIM(Raw_Bookings!F10)) -> MAU | P10: =UPPER(TRIM(Raw_Bookings!G10)) -> DEL | Q10: =IF(COUNTIF(Lookup_Stations!$A$2:$A$33,O10)>0,1,0) -> 1 | R10: =IF(COUNTIF(Lookup_Stations!$A$2:$A$33,P10)>0,1,0) -> 1 | S10: =IF(OR(AND(Q10=1,NOT(EXACT(Raw_Bookings!F10,O10))),AND(R10=1,NOT(EXACT(Raw_Bookings!G10,P10)))),1,0) -> 0 | T10: =IF(OR(Q10=0,R10=0),1,0) -> 0 | U10: =IF(TRIM(Raw_Bookings!E10&"")="",1,0) -> 0 | V10: =IF(SUMPRODUCT(--(Lookup_Status!$A$2:$A$13=LOWER(TRIM(Raw_Bookings!K10))))=0,"",INDEX(Lookup_Status!$B$2:$B$13,SUMPRODUCT((Lookup_Status!$A$2:$A$13=LOWER(TRIM(Raw_Bookings!K10)))*(ROW(Lookup_Status!$A$2:$A$13)-1)))) -> Confirmed | W10: =IF(AND(V10<>"",NOT(EXACT(Raw_Bookings!K10,V10))),1,0) -> 0 | X10: =IF(V10="",1,0) -> 0 | Y10: =IF(TRIM(Raw_Bookings!L10&"")="",1,0) -> 0 | Z10: =IF(AND(ISTEXT(Raw_Bookings!L10),Y10=0),1,0) -> 0 | AA10: =IF(Z10=1,IFERROR(VALUE(SUBSTITUTE(SUBSTITUTE(SUBSTITUTE(SUBSTITUTE(SUBSTITUTE(UPPER(Raw_Bookings!L10),"RS.",""),"₹",""),",","")," ",""),"INR","")),""),"") | AB10: =IF(AND(Z10=1,ISNUMBER(AA10)),1,0) -> 0 | AC10: =IF(B10=1,0,IF(NOT(ISNUMBER(Raw_Bookings!J10)),1,IF(Raw_Bookings!J10<>COUNTIFS(Work_Passengers!$B$2:$B$1336,Raw_Bookings!A10,Work_Passengers!$C$2:$C$1336,0),1,0))) -> 0
A11: =Raw_Bookings!A11 -> 1003617 | B11: =IF(COUNTIF(Raw_Bookings!$A$2:A11,Raw_Bookings!A11)>1,1,0) -> 0 | C11: =Raw_Bookings!D11&"" -> 2024-09-20 | D11: =IF(AND(LEN(C11)=10,MID(C11,5,1)="-",MID(C11,8,1)="-"),"ISO",IF(AND(LEN(C11)=10,MID(C11,3,1)="-",MID(C11,6,1)="-"),"DMY","OTHER")) -> ISO | E11: =IF(D11="ISO",VALUE(LEFT(C11,4)),IF(D11="DMY",VALUE(RIGHT(C11,4)),0)) -> 2024 | F11: =IF(D11="ISO",VALUE(MID(C11,6,2)),IF(D11="DMY",VALUE(MID(C11,4,2)),0)) -> 9 | G11: =IF(D11="ISO",VALUE(RIGHT(C11,2)),IF(D11="DMY",VALUE(LEFT(C11,2)),0)) -> 20 | H11: =IF(AND(D11<>"OTHER",F11>=1,F11<=12,G11>=1,G11<=31),IF(AND(MONTH(DATE(E11,F11,G11))=F11,DAY(DATE(E11,F11,G11))=G11),1,0),0) -> 1 | I11: =IF(H11=1,DATE(E11,F11,G11),"") -> 45555 | J11: =IF(AND(D11="DMY",H11=1),1,0) -> 0 | K11: =IF(H11=0,1,0) -> 0 | L11: =IF(TRIM(Raw_Bookings!I11&"")="",1,0) -> 0 | M11: =IF(L11=1,"",DATEVALUE(LEFT(Raw_Bookings!I11,10))+TIMEVALUE(MID(Raw_Bookings!I11,12,8))) -> 45518.1 | N11: =IF(AND(L11=0,H11=1),IF(INT(M11)>I11,1,0),0) -> 0 | O11: =UPPER(TRIM(Raw_Bookings!F11)) -> KOL | P11: =UPPER(TRIM(Raw_Bookings!G11)) -> HYD | Q11: =IF(COUNTIF(Lookup_Stations!$A$2:$A$33,O11)>0,1,0) -> 1 | R11: =IF(COUNTIF(Lookup_Stations!$A$2:$A$33,P11)>0,1,0) -> 1 | S11: =IF(OR(AND(Q11=1,NOT(EXACT(Raw_Bookings!F11,O11))),AND(R11=1,NOT(EXACT(Raw_Bookings!G11,P11)))),1,0) -> 0 | T11: =IF(OR(Q11=0,R11=0),1,0) -> 0 | U11: =IF(TRIM(Raw_Bookings!E11&"")="",1,0) -> 0 | V11: =IF(SUMPRODUCT(--(Lookup_Status!$A$2:$A$13=LOWER(TRIM(Raw_Bookings!K11))))=0,"",INDEX(Lookup_Status!$B$2:$B$13,SUMPRODUCT((Lookup_Status!$A$2:$A$13=LOWER(TRIM(Raw_Bookings!K11)))*(ROW(Lookup_Status!$A$2:$A$13)-1)))) -> Confirmed | W11: =IF(AND(V11<>"",NOT(EXACT(Raw_Bookings!K11,V11))),1,0) -> 0 | X11: =IF(V11="",1,0) -> 0 | Y11: =IF(TRIM(Raw_Bookings!L11&"")="",1,0) -> 0 | Z11: =IF(AND(ISTEXT(Raw_Bookings!L11),Y11=0),1,0) -> 0 | AA11: =IF(Z11=1,IFERROR(VALUE(SUBSTITUTE(SUBSTITUTE(SUBSTITUTE(SUBSTITUTE(SUBSTITUTE(UPPER(Raw_Bookings!L11),"RS.",""),"₹",""),",","")," ",""),"INR","")),""),"") | AB11: =IF(AND(Z11=1,ISNUMBER(AA11)),1,0) -> 0 | AC11: =IF(B11=1,0,IF(NOT(ISNUMBER(Raw_Bookings!J11)),1,IF(Raw_Bookings!J11<>COUNTIFS(Work_Passengers!$B$2:$B$1336,Raw_Bookings!A11,Work_Passengers!$C$2:$C$1336,0),1,0))) -> 0
