Workbook

Sheet Instructions
A1: Occupancy and Waitlist Tracker template (Google Sheets)
A2: SYNTHETIC SAMPLE DATA from a sampled simulation (768 simulated runs of 19,708 scheduled, 3.9%). Not IRCTC or Indian Railways metrics. Compare months with per-run and capacity-normalised measures, not raw monthly totals. Targets and thresholds are illustrative.
A4: 1. Import the .xlsx (File > Import). Enter one row per journey month and travel class on Inputs_Class_Month (yellow). Everything else is formulas.
A5: 2. Seat occupancy % = (confirmed passengers + RAC weight x RAC passengers) / available seats, on final statuses, matched per train-class run. The RAC weight (0.5) is a configurable simulation assumption on Settings, not an official rule.
A6: 3. Waitlisted passengers hold no seat: they are reported as waitlist pressure % (uncleared waitlist passengers / available seats) and are never part of occupancy. Confirmed, RAC and waitlisted passengers stay in separate columns.
A7: 4. By_Class and Month_x_Class summarise with SUMIFS as ratio of sums (never an average of percentages). The heat map on Month_x_Class shades occupancy.
A8: 5. Sample rows are synthetic, from a sampled simulation with simulated capacity. Occupancy here is whole-journey per train-class run; intermediate-segment occupancy is out of scope.

Sheet Settings
A1: Settings
A2: SYNTHETIC SAMPLE DATA from a sampled simulation (768 simulated runs of 19,708 scheduled, 3.9%). Not IRCTC or Indian Railways metrics. Compare months with per-run and capacity-normalised measures, not raw monthly totals. Targets and thresholds are illustrative.
A3: RAC seat weight (configurable simulation assumption) | B3: 0.5

Sheet Inputs_Class_Month
A1: Inputs: month x class (sample rows are synthetic)
A2: SYNTHETIC SAMPLE DATA from a sampled simulation (768 simulated runs of 19,708 scheduled, 3.9%). Not IRCTC or Indian Railways metrics. Compare months with per-run and capacity-normalised measures, not raw monthly totals. Targets and thresholds are illustrative.
A4: Journey month | B4: Travel class | C4: Class-runs | D4: Available seats | E4: Confirmed passengers | F4: RAC passengers | G4: Uncleared WL passengers | H4: Initially waitlisted passengers | I4: Total passengers
A5: 2024-09 | B5: 2A | C5: 15 | D5: 1058 | E5: 630 | F5: 31 | G5: 10 | H5: 12 | I5: 760
A6: 2024-09 | B6: 2S | C6: 17 | D6: 4644 | E6: 2748 | F6: 0 | G6: 225 | H6: 315 | I6: 3440
A7: 2024-09 | B7: 3A | C7: 31 | D7: 5184 | E7: 3159 | F7: 171 | G7: 57 | H7: 81 | I7: 3826
A8: 2024-09 | B8: CC | C8: 1 | D8: 312 | E8: 105 | F8: 0 | G8: 0 | H8: 0 | I8: 111
A9: 2024-09 | B9: SL | C9: 31 | D9: 5976 | E9: 3211 | F9: 147 | G9: 56 | H9: 82 | I9: 4022
A10: 2024-10 | B10: 1A | C10: 1 | D10: 24 | E10: 20 | F10: 0 | G10: 0 | H10: 0 | I10: 21
A11: 2024-10 | B11: 2A | C11: 16 | D11: 1242 | E11: 785 | F11: 18 | G11: 23 | H11: 37 | I11: 943
A12: 2024-10 | B12: 2S | C12: 16 | D12: 4752 | E12: 2953 | F12: 0 | G12: 276 | H12: 383 | I12: 3800
A13: 2024-10 | B13: 3A | C13: 30 | D13: 5056 | E13: 3600 | F13: 337 | G13: 161 | H13: 237 | I13: 4692
A14: 2024-10 | B14: CC | C14: 2 | D14: 390 | E14: 131 | F14: 0 | G14: 0 | H14: 0 | I14: 154
A15: 2024-10 | B15: SL | C15: 30 | D15: 6696 | E15: 4553 | F15: 386 | G15: 70 | H15: 113 | I15: 5838
A16: 2024-11 | B16: 1A | C16: 1 | D16: 24 | E16: 24 | F16: 0 | G16: 7 | H16: 7 | I16: 31
... A143: 2026-08 | B143: SL | C143: 29 | D143: 6336 | E143: 4703 | F143: 517 | G143: 411 | H143: 604 | I143: 6549

Sheet Analysis
A1: Row-level analysis (formulas; do not overwrite)
A2: SYNTHETIC SAMPLE DATA from a sampled simulation (768 simulated runs of 19,708 scheduled, 3.9%). Not IRCTC or Indian Railways metrics. Compare months with per-run and capacity-normalised measures, not raw monthly totals. Targets and thresholds are illustrative.
A4: Journey month | B4: Travel class | C4: Booked seats (seat-equivalents) | D4: Seat occupancy % | E4: Confirmed occupancy % | F4: RAC occupancy % | G4: Waitlist pressure % | H4: Passengers per class-run | I4: Initial WL per class-run
A5: =IF(Inputs_Class_Month!$A5="","",Inputs_Class_Month!$A5) -> 2024-09 | B5: =IF(Inputs_Class_Month!$B5="","",Inputs_Class_Month!$B5) -> 2A | C5: =IF(N(Inputs_Class_Month!$D5)=0,"",Inputs_Class_Month!$E5+Settings!$B$3*Inputs_Class_Month!$F5) -> 645.5 | D5: =IF(N(Inputs_Class_Month!$D5)=0,"",C5/Inputs_Class_Month!$D5) -> 0.61011342 | E5: =IF(N(Inputs_Class_Month!$D5)=0,"",Inputs_Class_Month!$E5/Inputs_Class_Month!$D5) -> 0.59546314 | F5: =IF(N(Inputs_Class_Month!$D5)=0,"",Settings!$B$3*Inputs_Class_Month!$F5/Inputs_Class_Month!$D5) -> 0.014650284 | G5: =IF(N(Inputs_Class_Month!$D5)=0,"",Inputs_Class_Month!$G5/Inputs_Class_Month!$D5) -> 0.0094517958 | H5: =IF(N(Inputs_Class_Month!$C5)=0,"",Inputs_Class_Month!$I5/Inputs_Class_Month!$C5) -> 50.666667 | I5: =IF(N(Inputs_Class_Month!$C5)=0,"",Inputs_Class_Month!$H5/Inputs_Class_Month!$C5) -> 0.8
A6: =IF(Inputs_Class_Month!$A6="","",Inputs_Class_Month!$A6) -> 2024-09 | B6: =IF(Inputs_Class_Month!$B6="","",Inputs_Class_Month!$B6) -> 2S | C6: =IF(N(Inputs_Class_Month!$D6)=0,"",Inputs_Class_Month!$E6+Settings!$B$3*Inputs_Class_Month!$F6) -> 2748 | D6: =IF(N(Inputs_Class_Month!$D6)=0,"",C6/Inputs_Class_Month!$D6) -> 0.59173127 | E6: =IF(N(Inputs_Class_Month!$D6)=0,"",Inputs_Class_Month!$E6/Inputs_Class_Month!$D6) -> 0.59173127 | F6: =IF(N(Inputs_Class_Month!$D6)=0,"",Settings!$B$3*Inputs_Class_Month!$F6/Inputs_Class_Month!$D6) -> 0 | G6: =IF(N(Inputs_Class_Month!$D6)=0,"",Inputs_Class_Month!$G6/Inputs_Class_Month!$D6) -> 0.048449612 | H6: =IF(N(Inputs_Class_Month!$C6)=0,"",Inputs_Class_Month!$I6/Inputs_Class_Month!$C6) -> 202.35294 | I6: =IF(N(Inputs_Class_Month!$C6)=0,"",Inputs_Class_Month!$H6/Inputs_Class_Month!$C6) -> 18.529412
A7: =IF(Inputs_Class_Month!$A7="","",Inputs_Class_Month!$A7) -> 2024-09 | B7: =IF(Inputs_Class_Month!$B7="","",Inputs_Class_Month!$B7) -> 3A | C7: =IF(N(Inputs_Class_Month!$D7)=0,"",Inputs_Class_Month!$E7+Settings!$B$3*Inputs_Class_Month!$F7) -> 3244.5 | D7: =IF(N(Inputs_Class_Month!$D7)=0,"",C7/Inputs_Class_Month!$D7) -> 0.62586806 | E7: =IF(N(Inputs_Class_Month!$D7)=0,"",Inputs_Class_Month!$E7/Inputs_Class_Month!$D7) -> 0.609375 | F7: =IF(N(Inputs_Class_Month!$D7)=0,"",Settings!$B$3*Inputs_Class_Month!$F7/Inputs_Class_Month!$D7) -> 0.016493056 | G7: =IF(N(Inputs_Class_Month!$D7)=0,"",Inputs_Class_Month!$G7/Inputs_Class_Month!$D7) -> 0.01099537 | H7: =IF(N(Inputs_Class_Month!$C7)=0,"",Inputs_Class_Month!$I7/Inputs_Class_Month!$C7) -> 123.41935 | I7: =IF(N(Inputs_Class_Month!$C7)=0,"",Inputs_Class_Month!$H7/Inputs_Class_Month!$C7) -> 2.6129032
A8: =IF(Inputs_Class_Month!$A8="","",Inputs_Class_Month!$A8) -> 2024-09 | B8: =IF(Inputs_Class_Month!$B8="","",Inputs_Class_Month!$B8) -> CC | C8: =IF(N(Inputs_Class_Month!$D8)=0,"",Inputs_Class_Month!$E8+Settings!$B$3*Inputs_Class_Month!$F8) -> 105 | D8: =IF(N(Inputs_Class_Month!$D8)=0,"",C8/Inputs_Class_Month!$D8) -> 0.33653846 | E8: =IF(N(Inputs_Class_Month!$D8)=0,"",Inputs_Class_Month!$E8/Inputs_Class_Month!$D8) -> 0.33653846 | F8: =IF(N(Inputs_Class_Month!$D8)=0,"",Settings!$B$3*Inputs_Class_Month!$F8/Inputs_Class_Month!$D8) -> 0 | G8: =IF(N(Inputs_Class_Month!$D8)=0,"",Inputs_Class_Month!$G8/Inputs_Class_Month!$D8) -> 0 | H8: =IF(N(Inputs_Class_Month!$C8)=0,"",Inputs_Class_Month!$I8/Inputs_Class_Month!$C8) -> 111 | I8: =IF(N(Inputs_Class_Month!$C8)=0,"",Inputs_Class_Month!$H8/Inputs_Class_Month!$C8) -> 0
A9: =IF(Inputs_Class_Month!$A9="","",Inputs_Class_Month!$A9) -> 2024-09 | B9: =IF(Inputs_Class_Month!$B9="","",Inputs_Class_Month!$B9) -> SL | C9: =IF(N(Inputs_Class_Month!$D9)=0,"",Inputs_Class_Month!$E9+Settings!$B$3*Inputs_Class_Month!$F9) -> 3284.5 | D9: =IF(N(Inputs_Class_Month!$D9)=0,"",C9/Inputs_Class_Month!$D9) -> 0.54961513 | E9: =IF(N(Inputs_Class_Month!$D9)=0,"",Inputs_Class_Month!$E9/Inputs_Class_Month!$D9) -> 0.53731593 | F9: =IF(N(Inputs_Class_Month!$D9)=0,"",Settings!$B$3*Inputs_Class_Month!$F9/Inputs_Class_Month!$D9) -> 0.012299197 | G9: =IF(N(Inputs_Class_Month!$D9)=0,"",Inputs_Class_Month!$G9/Inputs_Class_Month!$D9) -> 0.0093708166 | H9: =IF(N(Inputs_Class_Month!$C9)=0,"",Inputs_Class_Month!$I9/Inputs_Class_Month!$C9) -> 129.74194 | I9: =IF(N(Inputs_Class_Month!$C9)=0,"",Inputs_Class_Month!$H9/Inputs_Class_Month!$C9) -> 2.6451613
A10: =IF(Inputs_Class_Month!$A10="","",Inputs_Class_Month!$A10) -> 2024-10 | B10: =IF(Inputs_Class_Month!$B10="","",Inputs_Class_Month!$B10) -> 1A | C10: =IF(N(Inputs_Class_Month!$D10)=0,"",Inputs_Class_Month!$E10+Settings!$B$3*Inputs_Class_Month!$F10) -> 20 | D10: =IF(N(Inputs_Class_Month!$D10)=0,"",C10/Inputs_Class_Month!$D10) -> 0.83333333 | E10: =IF(N(Inputs_Class_Month!$D10)=0,"",Inputs_Class_Month!$E10/Inputs_Class_Month!$D10) -> 0.83333333 | F10: =IF(N(Inputs_Class_Month!$D10)=0,"",Settings!$B$3*Inputs_Class_Month!$F10/Inputs_Class_Month!$D10) -> 0 | G10: =IF(N(Inputs_Class_Month!$D10)=0,"",Inputs_Class_Month!$G10/Inputs_Class_Month!$D10) -> 0 | H10: =IF(N(Inputs_Class_Month!$C10)=0,"",Inputs_Class_Month!$I10/Inputs_Class_Month!$C10) -> 21 | I10: =IF(N(Inputs_Class_Month!$C10)=0,"",Inputs_Class_Month!$H10/Inputs_Class_Month!$C10) -> 0
A11: =IF(Inputs_Class_Month!$A11="","",Inputs_Class_Month!$A11) -> 2024-10 | B11: =IF(Inputs_Class_Month!$B11="","",Inputs_Class_Month!$B11) -> 2A | C11: =IF(N(Inputs_Class_Month!$D11)=0,"",Inputs_Class_Month!$E11+Settings!$B$3*Inputs_Class_Month!$F11) -> 794 | D11: =IF(N(Inputs_Class_Month!$D11)=0,"",C11/Inputs_Class_Month!$D11) -> 0.63929147 | E11: =IF(N(Inputs_Class_Month!$D11)=0,"",Inputs_Class_Month!$E11/Inputs_Class_Month!$D11) -> 0.63204509 | F11: =IF(N(Inputs_Class_Month!$D11)=0,"",Settings!$B$3*Inputs_Class_Month!$F11/Inputs_Class_Month!$D11) -> 0.0072463768 | G11: =IF(N(Inputs_Class_Month!$D11)=0,"",Inputs_Class_Month!$G11/Inputs_Class_Month!$D11) -> 0.018518519 | H11: =IF(N(Inputs_Class_Month!$C11)=0,"",Inputs_Class_Month!$I11/Inputs_Class_Month!$C11) -> 58.9375 | I11: =IF(N(Inputs_Class_Month!$C11)=0,"",Inputs_Class_Month!$H11/Inputs_Class_Month!$C11) -> 2.3125
A12: =IF(Inputs_Class_Month!$A12="","",Inputs_Class_Month!$A12) -> 2024-10 | B12: =IF(Inputs_Class_Month!$B12="","",Inputs_Class_Month!$B12) -> 2S | C12: =IF(N(Inputs_Class_Month!$D12)=0,"",Inputs_Class_Month!$E12+Settings!$B$3*Inputs_Class_Month!$F12) -> 2953 | D12: =IF(N(Inputs_Class_Month!$D12)=0,"",C12/Inputs_Class_Month!$D12) -> 0.62142256 | E12: =IF(N(Inputs_Class_Month!$D12)=0,"",Inputs_Class_Month!$E12/Inputs_Class_Month!$D12) -> 0.62142256 | F12: =IF(N(Inputs_Class_Month!$D12)=0,"",Settings!$B$3*Inputs_Class_Month!$F12/Inputs_Class_Month!$D12) -> 0 | G12: =IF(N(Inputs_Class_Month!$D12)=0,"",Inputs_Class_Month!$G12/Inputs_Class_Month!$D12) -> 0.058080808 | H12: =IF(N(Inputs_Class_Month!$C12)=0,"",Inputs_Class_Month!$I12/Inputs_Class_Month!$C12) -> 237.5 | I12: =IF(N(Inputs_Class_Month!$C12)=0,"",Inputs_Class_Month!$H12/Inputs_Class_Month!$C12) -> 23.9375
A13: =IF(Inputs_Class_Month!$A13="","",Inputs_Class_Month!$A13) -> 2024-10 | B13: =IF(Inputs_Class_Month!$B13="","",Inputs_Class_Month!$B13) -> 3A | C13: =IF(N(Inputs_Class_Month!$D13)=0,"",Inputs_Class_Month!$E13+Settings!$B$3*Inputs_Class_Month!$F13) -> 3768.5 | D13: =IF(N(Inputs_Class_Month!$D13)=0,"",C13/Inputs_Class_Month!$D13) -> 0.74535206 | E13: =IF(N(Inputs_Class_Month!$D13)=0,"",Inputs_Class_Month!$E13/Inputs_Class_Month!$D13) -> 0.71202532 | F13: =IF(N(Inputs_Class_Month!$D13)=0,"",Settings!$B$3*Inputs_Class_Month!$F13/Inputs_Class_Month!$D13) -> 0.033326741 | G13: =IF(N(Inputs_Class_Month!$D13)=0,"",Inputs_Class_Month!$G13/Inputs_Class_Month!$D13) -> 0.031843354 | H13: =IF(N(Inputs_Class_Month!$C13)=0,"",Inputs_Class_Month!$I13/Inputs_Class_Month!$C13) -> 156.4 | I13: =IF(N(Inputs_Class_Month!$C13)=0,"",Inputs_Class_Month!$H13/Inputs_Class_Month!$C13) -> 7.9
A14: =IF(Inputs_Class_Month!$A14="","",Inputs_Class_Month!$A14) -> 2024-10 | B14: =IF(Inputs_Class_Month!$B14="","",Inputs_Class_Month!$B14) -> CC | C14: =IF(N(Inputs_Class_Month!$D14)=0,"",Inputs_Class_Month!$E14+Settings!$B$3*Inputs_Class_Month!$F14) -> 131 | D14: =IF(N(Inputs_Class_Month!$D14)=0,"",C14/Inputs_Class_Month!$D14) -> 0.33589744 | E14: =IF(N(Inputs_Class_Month!$D14)=0,"",Inputs_Class_Month!$E14/Inputs_Class_Month!$D14) -> 0.33589744 | F14: =IF(N(Inputs_Class_Month!$D14)=0,"",Settings!$B$3*Inputs_Class_Month!$F14/Inputs_Class_Month!$D14) -> 0 | G14: =IF(N(Inputs_Class_Month!$D14)=0,"",Inputs_Class_Month!$G14/Inputs_Class_Month!$D14) -> 0 | H14: =IF(N(Inputs_Class_Month!$C14)=0,"",Inputs_Class_Month!$I14/Inputs_Class_Month!$C14) -> 77 | I14: =IF(N(Inputs_Class_Month!$C14)=0,"",Inputs_Class_Month!$H14/Inputs_Class_Month!$C14) -> 0
A15: =IF(Inputs_Class_Month!$A15="","",Inputs_Class_Month!$A15) -> 2024-10 | B15: =IF(Inputs_Class_Month!$B15="","",Inputs_Class_Month!$B15) -> SL | C15: =IF(N(Inputs_Class_Month!$D15)=0,"",Inputs_Class_Month!$E15+Settings!$B$3*Inputs_Class_Month!$F15) -> 4746 | D15: =IF(N(Inputs_Class_Month!$D15)=0,"",C15/Inputs_Class_Month!$D15) -> 0.70878136 | E15: =IF(N(Inputs_Class_Month!$D15)=0,"",Inputs_Class_Month!$E15/Inputs_Class_Month!$D15) -> 0.67995818 | F15: =IF(N(Inputs_Class_Month!$D15)=0,"",Settings!$B$3*Inputs_Class_Month!$F15/Inputs_Class_Month!$D15) -> 0.028823178 | G15: =IF(N(Inputs_Class_Month!$D15)=0,"",Inputs_Class_Month!$G15/Inputs_Class_Month!$D15) -> 0.010454002 | H15: =IF(N(Inputs_Class_Month!$C15)=0,"",Inputs_Class_Month!$I15/Inputs_Class_Month!$C15) -> 194.6 | I15: =IF(N(Inputs_Class_Month!$C15)=0,"",Inputs_Class_Month!$H15/Inputs_Class_Month!$C15) -> 3.7666667
A16: =IF(Inputs_Class_Month!$A16="","",Inputs_Class_Month!$A16) -> 2024-11 | B16: =IF(Inputs_Class_Month!$B16="","",Inputs_Class_Month!$B16) -> 1A | C16: =IF(N(Inputs_Class_Month!$D16)=0,"",Inputs_Class_Month!$E16+Settings!$B$3*Inputs_Class_Month!$F16) -> 24 | D16: =IF(N(Inputs_Class_Month!$D16)=0,"",C16/Inputs_Class_Month!$D16) -> 1 | E16: =IF(N(Inputs_Class_Month!$D16)=0,"",Inputs_Class_Month!$E16/Inputs_Class_Month!$D16) -> 1 | F16: =IF(N(Inputs_Class_Month!$D16)=0,"",Settings!$B$3*Inputs_Class_Month!$F16/Inputs_Class_Month!$D16) -> 0 | G16: =IF(N(Inputs_Class_Month!$D16)=0,"",Inputs_Class_Month!$G16/Inputs_Class_Month!$D16) -> 0.29166667 | H16: =IF(N(Inputs_Class_Month!$C16)=0,"",Inputs_Class_Month!$I16/Inputs_Class_Month!$C16) -> 31 | I16: =IF(N(Inputs_Class_Month!$C16)=0,"",Inputs_Class_Month!$H16/Inputs_Class_Month!$C16) -> 7
... A203: =IF(Inputs_Class_Month!$A203="","",Inputs_Class_Month!$A203) | B203: =IF(Inputs_Class_Month!$B203="","",Inputs_Class_Month!$B203) | C203: =IF(N(Inputs_Class_Month!$D203)=0,"",Inputs_Class_Month!$E203+Settings!$B$3*Inputs_Class_Month!$F203) | D203: =IF(N(Inputs_Class_Month!$D203)=0,"",C203/Inputs_Class_Month!$D203) | E203: =IF(N(Inputs_Class_Month!$D203)=0,"",Inputs_Class_Month!$E203/Inputs_Class_Month!$D203) | F203: =IF(N(Inputs_Class_Month!$D203)=0,"",Settings!$B$3*Inputs_Class_Month!$F203/Inputs_Class_Month!$D203) | G203: =IF(N(Inputs_Class_Month!$D203)=0,"",Inputs_Class_Month!$G203/Inputs_Class_Month!$D203) | H203: =IF(N(Inputs_Class_Month!$C203)=0,"",Inputs_Class_Month!$I203/Inputs_Class_Month!$C203) | I203: =IF(N(Inputs_Class_Month!$C203)=0,"",Inputs_Class_Month!$H203/Inputs_Class_Month!$C203)

Sheet By_Class
A1: Summary by travel class (ratio of sums)
A2: SYNTHETIC SAMPLE DATA from a sampled simulation (768 simulated runs of 19,708 scheduled, 3.9%). Not IRCTC or Indian Railways metrics. Compare months with per-run and capacity-normalised measures, not raw monthly totals. Targets and thresholds are illustrative.
A4: Class | B4: Class-runs | C4: Available seats | D4: Booked seats | E4: Seat occupancy % | F4: Confirmed occupancy % | G4: RAC occupancy % | H4: Waitlist pressure %
A5: SL | B5: =SUMIFS(Inputs_Class_Month!$C$5:$C$203,Inputs_Class_Month!$B$5:$B$203,A5) -> 720 | C5: =SUMIFS(Inputs_Class_Month!$D$5:$D$203,Inputs_Class_Month!$B$5:$B$203,A5) -> 154368 | D5: =SUMIFS(Inputs_Class_Month!$E$5:$E$203,Inputs_Class_Month!$B$5:$B$203,A5)+Settings!$B$3*SUMIFS(Inputs_Class_Month!$F$5:$F$203,Inputs_Class_Month!$B$5:$B$203,A5) -> 116151 | E5: =IF(C5=0,"",D5/C5) -> 0.75242926 | F5: =IF(C5=0,"",SUMIFS(Inputs_Class_Month!$E$5:$E$203,Inputs_Class_Month!$B$5:$B$203,A5)/C5) -> 0.71355462 | G5: =IF(C5=0,"",Settings!$B$3*SUMIFS(Inputs_Class_Month!$F$5:$F$203,Inputs_Class_Month!$B$5:$B$203,A5)/C5) -> 0.038874637 | H5: =IF(C5=0,"",SUMIFS(Inputs_Class_Month!$G$5:$G$203,Inputs_Class_Month!$B$5:$B$203,A5)/C5) -> 0.061068356
A6: 3A | B6: =SUMIFS(Inputs_Class_Month!$C$5:$C$203,Inputs_Class_Month!$B$5:$B$203,A6) -> 734 | C6: =SUMIFS(Inputs_Class_Month!$D$5:$D$203,Inputs_Class_Month!$B$5:$B$203,A6) -> 122368 | D6: =SUMIFS(Inputs_Class_Month!$E$5:$E$203,Inputs_Class_Month!$B$5:$B$203,A6)+Settings!$B$3*SUMIFS(Inputs_Class_Month!$F$5:$F$203,Inputs_Class_Month!$B$5:$B$203,A6) -> 93992 | E6: =IF(C6=0,"",D6/C6) -> 0.76810931 | F6: =IF(C6=0,"",SUMIFS(Inputs_Class_Month!$E$5:$E$203,Inputs_Class_Month!$B$5:$B$203,A6)/C6) -> 0.72813971 | G6: =IF(C6=0,"",Settings!$B$3*SUMIFS(Inputs_Class_Month!$F$5:$F$203,Inputs_Class_Month!$B$5:$B$203,A6)/C6) -> 0.0399696 | H6: =IF(C6=0,"",SUMIFS(Inputs_Class_Month!$G$5:$G$203,Inputs_Class_Month!$B$5:$B$203,A6)/C6) -> 0.065343881
A7: 2A | B7: =SUMIFS(Inputs_Class_Month!$C$5:$C$203,Inputs_Class_Month!$B$5:$B$203,A7) -> 351 | C7: =SUMIFS(Inputs_Class_Month!$D$5:$D$203,Inputs_Class_Month!$B$5:$B$203,A7) -> 25760 | D7: =SUMIFS(Inputs_Class_Month!$E$5:$E$203,Inputs_Class_Month!$B$5:$B$203,A7)+Settings!$B$3*SUMIFS(Inputs_Class_Month!$F$5:$F$203,Inputs_Class_Month!$B$5:$B$203,A7) -> 18724.5 | E7: =IF(C7=0,"",D7/C7) -> 0.72688276 | F7: =IF(C7=0,"",SUMIFS(Inputs_Class_Month!$E$5:$E$203,Inputs_Class_Month!$B$5:$B$203,A7)/C7) -> 0.69650621 | G7: =IF(C7=0,"",Settings!$B$3*SUMIFS(Inputs_Class_Month!$F$5:$F$203,Inputs_Class_Month!$B$5:$B$203,A7)/C7) -> 0.030376553 | H7: =IF(C7=0,"",SUMIFS(Inputs_Class_Month!$G$5:$G$203,Inputs_Class_Month!$B$5:$B$203,A7)/C7) -> 0.044798137
A8: 1A | B8: =SUMIFS(Inputs_Class_Month!$C$5:$C$203,Inputs_Class_Month!$B$5:$B$203,A8) -> 29 | C8: =SUMIFS(Inputs_Class_Month!$D$5:$D$203,Inputs_Class_Month!$B$5:$B$203,A8) -> 768 | D8: =SUMIFS(Inputs_Class_Month!$E$5:$E$203,Inputs_Class_Month!$B$5:$B$203,A8)+Settings!$B$3*SUMIFS(Inputs_Class_Month!$F$5:$F$203,Inputs_Class_Month!$B$5:$B$203,A8) -> 563 | E8: =IF(C8=0,"",D8/C8) -> 0.73307292 | F8: =IF(C8=0,"",SUMIFS(Inputs_Class_Month!$E$5:$E$203,Inputs_Class_Month!$B$5:$B$203,A8)/C8) -> 0.73307292 | G8: =IF(C8=0,"",Settings!$B$3*SUMIFS(Inputs_Class_Month!$F$5:$F$203,Inputs_Class_Month!$B$5:$B$203,A8)/C8) -> 0 | H8: =IF(C8=0,"",SUMIFS(Inputs_Class_Month!$G$5:$G$203,Inputs_Class_Month!$B$5:$B$203,A8)/C8) -> 0.033854167
A9: CC | B9: =SUMIFS(Inputs_Class_Month!$C$5:$C$203,Inputs_Class_Month!$B$5:$B$203,A9) -> 34 | C9: =SUMIFS(Inputs_Class_Month!$D$5:$D$203,Inputs_Class_Month!$B$5:$B$203,A9) -> 7020 | D9: =SUMIFS(Inputs_Class_Month!$E$5:$E$203,Inputs_Class_Month!$B$5:$B$203,A9)+Settings!$B$3*SUMIFS(Inputs_Class_Month!$F$5:$F$203,Inputs_Class_Month!$B$5:$B$203,A9) -> 3688 | E9: =IF(C9=0,"",D9/C9) -> 0.52535613 | F9: =IF(C9=0,"",SUMIFS(Inputs_Class_Month!$E$5:$E$203,Inputs_Class_Month!$B$5:$B$203,A9)/C9) -> 0.52535613 | G9: =IF(C9=0,"",Settings!$B$3*SUMIFS(Inputs_Class_Month!$F$5:$F$203,Inputs_Class_Month!$B$5:$B$203,A9)/C9) -> 0 | H9: =IF(C9=0,"",SUMIFS(Inputs_Class_Month!$G$5:$G$203,Inputs_Class_Month!$B$5:$B$203,A9)/C9) -> 0.0032763533
A10: 2S | B10: =SUMIFS(Inputs_Class_Month!$C$5:$C$203,Inputs_Class_Month!$B$5:$B$203,A10) -> 417 | C10: =SUMIFS(Inputs_Class_Month!$D$5:$D$203,Inputs_Class_Month!$B$5:$B$203,A10) -> 116100 | D10: =SUMIFS(Inputs_Class_Month!$E$5:$E$203,Inputs_Class_Month!$B$5:$B$203,A10)+Settings!$B$3*SUMIFS(Inputs_Class_Month!$F$5:$F$203,Inputs_Class_Month!$B$5:$B$203,A10) -> 80227 | E10: =IF(C10=0,"",D10/C10) -> 0.69101637 | F10: =IF(C10=0,"",SUMIFS(Inputs_Class_Month!$E$5:$E$203,Inputs_Class_Month!$B$5:$B$203,A10)/C10) -> 0.69101637 | G10: =IF(C10=0,"",Settings!$B$3*SUMIFS(Inputs_Class_Month!$F$5:$F$203,Inputs_Class_Month!$B$5:$B$203,A10)/C10) -> 0 | H10: =IF(C10=0,"",SUMIFS(Inputs_Class_Month!$G$5:$G$203,Inputs_Class_Month!$B$5:$B$203,A10)/C10) -> 0.048010336
A11: All classes | B11: =SUM(Inputs_Class_Month!$C$5:$C$203) -> 2285 | C11: =SUM(Inputs_Class_Month!$D$5:$D$203) -> 426384 | D11: =SUM(Inputs_Class_Month!$E$5:$E$203)+Settings!$B$3*SUM(Inputs_Class_Month!$F$5:$F$203) -> 313345.5 | E11: =IF(C11=0,"",D11/C11) -> 0.73489038 | F11: =IF(C11=0,"",SUM(Inputs_Class_Month!$E$5:$E$203)/C11) -> 0.70751013 | G11: =IF(C11=0,"",Settings!$B$3*SUM(Inputs_Class_Month!$F$5:$F$203)/C11) -> 0.027380249 | H11: =IF(C11=0,"",SUM(Inputs_Class_Month!$G$5:$G$203)/C11) -> 0.056756351

Sheet Month_x_Class
A1: Seat occupancy % heat map: month x class (ratio of sums)
A2: SYNTHETIC SAMPLE DATA from a sampled simulation (768 simulated runs of 19,708 scheduled, 3.9%). Not IRCTC or Indian Railways metrics. Compare months with per-run and capacity-normalised measures, not raw monthly totals. Targets and thresholds are illustrative.
A4: Journey month | B4: SL | C4: 3A | D4: 2A | E4: 1A | F4: CC | G4: 2S | H4: All classes
A5: 2024-09 | B5: =IF(SUMIFS(Inputs_Class_Month!$D$5:$D$203,Inputs_Class_Month!$A$5:$A$203,$A5,Inputs_Class_Month!$B$5:$B$203,B$4)=0,"",(SUMIFS(Inputs_Class_Month!$E$5:$E$203,Inputs_Class_Month!$A$5:$A$203,$A5,Inputs_Class_Month!$B$5:$B$203,B$4)+Settings!$B$3*SUMIFS(Inputs_Class_Month!$F$5:$F$203,Inputs_Class_Month!$A$5:$A$203,$A5,Inputs_Class_Month!$B$5:$B$203,B$4))/SUMIFS(Inputs_Class_Month!$D$5:$D$203,Inputs_Class_Month!$A$5:$A$203,$A5,Inputs_Class_Month!$B$5:$B$203,B$4)) -> 0.54961513 | C5: =IF(SUMIFS(Inputs_Class_Month!$D$5:$D$203,Inputs_Class_Month!$A$5:$A$203,$A5,Inputs_Class_Month!$B$5:$B$203,C$4)=0,"",(SUMIFS(Inputs_Class_Month!$E$5:$E$203,Inputs_Class_Month!$A$5:$A$203,$A5,Inputs_Class_Month!$B$5:$B$203,C$4)+Settings!$B$3*SUMIFS(Inputs_Class_Month!$F$5:$F$203,Inputs_Class_Month!$A$5:$A$203,$A5,Inputs_Class_Month!$B$5:$B$203,C$4))/SUMIFS(Inputs_Class_Month!$D$5:$D$203,Inputs_Class_Month!$A$5:$A$203,$A5,Inputs_Class_Month!$B$5:$B$203,C$4)) -> 0.62586806 | D5: =IF(SUMIFS(Inputs_Class_Month!$D$5:$D$203,Inputs_Class_Month!$A$5:$A$203,$A5,Inputs_Class_Month!$B$5:$B$203,D$4)=0,"",(SUMIFS(Inputs_Class_Month!$E$5:$E$203,Inputs_Class_Month!$A$5:$A$203,$A5,Inputs_Class_Month!$B$5:$B$203,D$4)+Settings!$B$3*SUMIFS(Inputs_Class_Month!$F$5:$F$203,Inputs_Class_Month!$A$5:$A$203,$A5,Inputs_Class_Month!$B$5:$B$203,D$4))/SUMIFS(Inputs_Class_Month!$D$5:$D$203,Inputs_Class_Month!$A$5:$A$203,$A5,Inputs_Class_Month!$B$5:$B$203,D$4)) -> 0.61011342 | E5: =IF(SUMIFS(Inputs_Class_Month!$D$5:$D$203,Inputs_Class_Month!$A$5:$A$203,$A5,Inputs_Class_Month!$B$5:$B$203,E$4)=0,"",(SUMIFS(Inputs_Class_Month!$E$5:$E$203,Inputs_Class_Month!$A$5:$A$203,$A5,Inputs_Class_Month!$B$5:$B$203,E$4)+Settings!$B$3*SUMIFS(Inputs_Class_Month!$F$5:$F$203,Inputs_Class_Month!$A$5:$A$203,$A5,Inputs_Class_Month!$B$5:$B$203,E$4))/SUMIFS(Inputs_Class_Month!$D$5:$D$203,Inputs_Class_Month!$A$5:$A$203,$A5,Inputs_Class_Month!$B$5:$B$203,E$4)) | F5: =IF(SUMIFS(Inputs_Class_Month!$D$5:$D$203,Inputs_Class_Month!$A$5:$A$203,$A5,Inputs_Class_Month!$B$5:$B$203,F$4)=0,"",(SUMIFS(Inputs_Class_Month!$E$5:$E$203,Inputs_Class_Month!$A$5:$A$203,$A5,Inputs_Class_Month!$B$5:$B$203,F$4)+Settings!$B$3*SUMIFS(Inputs_Class_Month!$F$5:$F$203,Inputs_Class_Month!$A$5:$A$203,$A5,Inputs_Class_Month!$B$5:$B$203,F$4))/SUMIFS(Inputs_Class_Month!$D$5:$D$203,Inputs_Class_Month!$A$5:$A$203,$A5,Inputs_Class_Month!$B$5:$B$203,F$4)) -> 0.33653846 | G5: =IF(SUMIFS(Inputs_Class_Month!$D$5:$D$203,Inputs_Class_Month!$A$5:$A$203,$A5,Inputs_Class_Month!$B$5:$B$203,G$4)=0,"",(SUMIFS(Inputs_Class_Month!$E$5:$E$203,Inputs_Class_Month!$A$5:$A$203,$A5,Inputs_Class_Month!$B$5:$B$203,G$4)+Settings!$B$3*SUMIFS(Inputs_Class_Month!$F$5:$F$203,Inputs_Class_Month!$A$5:$A$203,$A5,Inputs_Class_Month!$B$5:$B$203,G$4))/SUMIFS(Inputs_Class_Month!$D$5:$D$203,Inputs_Class_Month!$A$5:$A$203,$A5,Inputs_Class_Month!$B$5:$B$203,G$4)) -> 0.59173127 | H5: =IF(SUMIFS(Inputs_Class_Month!$D$5:$D$203,Inputs_Class_Month!$A$5:$A$203,$A5)=0,"",(SUMIFS(Inputs_Class_Month!$E$5:$E$203,Inputs_Class_Month!$A$5:$A$203,$A5)+Settings!$B$3*SUMIFS(Inputs_Class_Month!$F$5:$F$203,Inputs_Class_Month!$A$5:$A$203,$A5))/SUMIFS(Inputs_Class_Month!$D$5:$D$203,Inputs_Class_Month!$A$5:$A$203,$A5)) -> 0.58387679
A6: 2024-10 | B6: =IF(SUMIFS(Inputs_Class_Month!$D$5:$D$203,Inputs_Class_Month!$A$5:$A$203,$A6,Inputs_Class_Month!$B$5:$B$203,B$4)=0,"",(SUMIFS(Inputs_Class_Month!$E$5:$E$203,Inputs_Class_Month!$A$5:$A$203,$A6,Inputs_Class_Month!$B$5:$B$203,B$4)+Settings!$B$3*SUMIFS(Inputs_Class_Month!$F$5:$F$203,Inputs_Class_Month!$A$5:$A$203,$A6,Inputs_Class_Month!$B$5:$B$203,B$4))/SUMIFS(Inputs_Class_Month!$D$5:$D$203,Inputs_Class_Month!$A$5:$A$203,$A6,Inputs_Class_Month!$B$5:$B$203,B$4)) -> 0.70878136 | C6: =IF(SUMIFS(Inputs_Class_Month!$D$5:$D$203,Inputs_Class_Month!$A$5:$A$203,$A6,Inputs_Class_Month!$B$5:$B$203,C$4)=0,"",(SUMIFS(Inputs_Class_Month!$E$5:$E$203,Inputs_Class_Month!$A$5:$A$203,$A6,Inputs_Class_Month!$B$5:$B$203,C$4)+Settings!$B$3*SUMIFS(Inputs_Class_Month!$F$5:$F$203,Inputs_Class_Month!$A$5:$A$203,$A6,Inputs_Class_Month!$B$5:$B$203,C$4))/SUMIFS(Inputs_Class_Month!$D$5:$D$203,Inputs_Class_Month!$A$5:$A$203,$A6,Inputs_Class_Month!$B$5:$B$203,C$4)) -> 0.74535206 | D6: =IF(SUMIFS(Inputs_Class_Month!$D$5:$D$203,Inputs_Class_Month!$A$5:$A$203,$A6,Inputs_Class_Month!$B$5:$B$203,D$4)=0,"",(SUMIFS(Inputs_Class_Month!$E$5:$E$203,Inputs_Class_Month!$A$5:$A$203,$A6,Inputs_Class_Month!$B$5:$B$203,D$4)+Settings!$B$3*SUMIFS(Inputs_Class_Month!$F$5:$F$203,Inputs_Class_Month!$A$5:$A$203,$A6,Inputs_Class_Month!$B$5:$B$203,D$4))/SUMIFS(Inputs_Class_Month!$D$5:$D$203,Inputs_Class_Month!$A$5:$A$203,$A6,Inputs_Class_Month!$B$5:$B$203,D$4)) -> 0.63929147 | E6: =IF(SUMIFS(Inputs_Class_Month!$D$5:$D$203,Inputs_Class_Month!$A$5:$A$203,$A6,Inputs_Class_Month!$B$5:$B$203,E$4)=0,"",(SUMIFS(Inputs_Class_Month!$E$5:$E$203,Inputs_Class_Month!$A$5:$A$203,$A6,Inputs_Class_Month!$B$5:$B$203,E$4)+Settings!$B$3*SUMIFS(Inputs_Class_Month!$F$5:$F$203,Inputs_Class_Month!$A$5:$A$203,$A6,Inputs_Class_Month!$B$5:$B$203,E$4))/SUMIFS(Inputs_Class_Month!$D$5:$D$203,Inputs_Class_Month!$A$5:$A$203,$A6,Inputs_Class_Month!$B$5:$B$203,E$4)) -> 0.83333333 | F6: =IF(SUMIFS(Inputs_Class_Month!$D$5:$D$203,Inputs_Class_Month!$A$5:$A$203,$A6,Inputs_Class_Month!$B$5:$B$203,F$4)=0,"",(SUMIFS(Inputs_Class_Month!$E$5:$E$203,Inputs_Class_Month!$A$5:$A$203,$A6,Inputs_Class_Month!$B$5:$B$203,F$4)+Settings!$B$3*SUMIFS(Inputs_Class_Month!$F$5:$F$203,Inputs_Class_Month!$A$5:$A$203,$A6,Inputs_Class_Month!$B$5:$B$203,F$4))/SUMIFS(Inputs_Class_Month!$D$5:$D$203,Inputs_Class_Month!$A$5:$A$203,$A6,Inputs_Class_Month!$B$5:$B$203,F$4)) -> 0.33589744 | G6: =IF(SUMIFS(Inputs_Class_Month!$D$5:$D$203,Inputs_Class_Month!$A$5:$A$203,$A6,Inputs_Class_Month!$B$5:$B$203,G$4)=0,"",(SUMIFS(Inputs_Class_Month!$E$5:$E$203,Inputs_Class_Month!$A$5:$A$203,$A6,Inputs_Class_Month!$B$5:$B$203,G$4)+Settings!$B$3*SUMIFS(Inputs_Class_Month!$F$5:$F$203,Inputs_Class_Month!$A$5:$A$203,$A6,Inputs_Class_Month!$B$5:$B$203,G$4))/SUMIFS(Inputs_Class_Month!$D$5:$D$203,Inputs_Class_Month!$A$5:$A$203,$A6,Inputs_Class_Month!$B$5:$B$203,G$4)) -> 0.62142256 | H6: =IF(SUMIFS(Inputs_Class_Month!$D$5:$D$203,Inputs_Class_Month!$A$5:$A$203,$A6)=0,"",(SUMIFS(Inputs_Class_Month!$E$5:$E$203,Inputs_Class_Month!$A$5:$A$203,$A6)+Settings!$B$3*SUMIFS(Inputs_Class_Month!$F$5:$F$203,Inputs_Class_Month!$A$5:$A$203,$A6))/SUMIFS(Inputs_Class_Month!$D$5:$D$203,Inputs_Class_Month!$A$5:$A$203,$A6)) -> 0.68350771
A7: 2024-11 | B7: =IF(SUMIFS(Inputs_Class_Month!$D$5:$D$203,Inputs_Class_Month!$A$5:$A$203,$A7,Inputs_Class_Month!$B$5:$B$203,B$4)=0,"",(SUMIFS(Inputs_Class_Month!$E$5:$E$203,Inputs_Class_Month!$A$5:$A$203,$A7,Inputs_Class_Month!$B$5:$B$203,B$4)+Settings!$B$3*SUMIFS(Inputs_Class_Month!$F$5:$F$203,Inputs_Class_Month!$A$5:$A$203,$A7,Inputs_Class_Month!$B$5:$B$203,B$4))/SUMIFS(Inputs_Class_Month!$D$5:$D$203,Inputs_Class_Month!$A$5:$A$203,$A7,Inputs_Class_Month!$B$5:$B$203,B$4)) -> 0.71227904 | C7: =IF(SUMIFS(Inputs_Class_Month!$D$5:$D$203,Inputs_Class_Month!$A$5:$A$203,$A7,Inputs_Class_Month!$B$5:$B$203,C$4)=0,"",(SUMIFS(Inputs_Class_Month!$E$5:$E$203,Inputs_Class_Month!$A$5:$A$203,$A7,Inputs_Class_Month!$B$5:$B$203,C$4)+Settings!$B$3*SUMIFS(Inputs_Class_Month!$F$5:$F$203,Inputs_Class_Month!$A$5:$A$203,$A7,Inputs_Class_Month!$B$5:$B$203,C$4))/SUMIFS(Inputs_Class_Month!$D$5:$D$203,Inputs_Class_Month!$A$5:$A$203,$A7,Inputs_Class_Month!$B$5:$B$203,C$4)) -> 0.75517578 | D7: =IF(SUMIFS(Inputs_Class_Month!$D$5:$D$203,Inputs_Class_Month!$A$5:$A$203,$A7,Inputs_Class_Month!$B$5:$B$203,D$4)=0,"",(SUMIFS(Inputs_Class_Month!$E$5:$E$203,Inputs_Class_Month!$A$5:$A$203,$A7,Inputs_Class_Month!$B$5:$B$203,D$4)+Settings!$B$3*SUMIFS(Inputs_Class_Month!$F$5:$F$203,Inputs_Class_Month!$A$5:$A$203,$A7,Inputs_Class_Month!$B$5:$B$203,D$4))/SUMIFS(Inputs_Class_Month!$D$5:$D$203,Inputs_Class_Month!$A$5:$A$203,$A7,Inputs_Class_Month!$B$5:$B$203,D$4)) -> 0.72722567 | E7: =IF(SUMIFS(Inputs_Class_Month!$D$5:$D$203,Inputs_Class_Month!$A$5:$A$203,$A7,Inputs_Class_Month!$B$5:$B$203,E$4)=0,"",(SUMIFS(Inputs_Class_Month!$E$5:$E$203,Inputs_Class_Month!$A$5:$A$203,$A7,Inputs_Class_Month!$B$5:$B$203,E$4)+Settings!$B$3*SUMIFS(Inputs_Class_Month!$F$5:$F$203,Inputs_Class_Month!$A$5:$A$203,$A7,Inputs_Class_Month!$B$5:$B$203,E$4))/SUMIFS(Inputs_Class_Month!$D$5:$D$203,Inputs_Class_Month!$A$5:$A$203,$A7,Inputs_Class_Month!$B$5:$B$203,E$4)) -> 1 | F7: =IF(SUMIFS(Inputs_Class_Month!$D$5:$D$203,Inputs_Class_Month!$A$5:$A$203,$A7,Inputs_Class_Month!$B$5:$B$203,F$4)=0,"",(SUMIFS(Inputs_Class_Month!$E$5:$E$203,Inputs_Class_Month!$A$5:$A$203,$A7,Inputs_Class_Month!$B$5:$B$203,F$4)+Settings!$B$3*SUMIFS(Inputs_Class_Month!$F$5:$F$203,Inputs_Class_Month!$A$5:$A$203,$A7,Inputs_Class_Month!$B$5:$B$203,F$4))/SUMIFS(Inputs_Class_Month!$D$5:$D$203,Inputs_Class_Month!$A$5:$A$203,$A7,Inputs_Class_Month!$B$5:$B$203,F$4)) | G7: =IF(SUMIFS(Inputs_Class_Month!$D$5:$D$203,Inputs_Class_Month!$A$5:$A$203,$A7,Inputs_Class_Month!$B$5:$B$203,G$4)=0,"",(SUMIFS(Inputs_Class_Month!$E$5:$E$203,Inputs_Class_Month!$A$5:$A$203,$A7,Inputs_Class_Month!$B$5:$B$203,G$4)+Settings!$B$3*SUMIFS(Inputs_Class_Month!$F$5:$F$203,Inputs_Class_Month!$A$5:$A$203,$A7,Inputs_Class_Month!$B$5:$B$203,G$4))/SUMIFS(Inputs_Class_Month!$D$5:$D$203,Inputs_Class_Month!$A$5:$A$203,$A7,Inputs_Class_Month!$B$5:$B$203,G$4)) -> 0.63114135 | H7: =IF(SUMIFS(Inputs_Class_Month!$D$5:$D$203,Inputs_Class_Month!$A$5:$A$203,$A7)=0,"",(SUMIFS(Inputs_Class_Month!$E$5:$E$203,Inputs_Class_Month!$A$5:$A$203,$A7)+Settings!$B$3*SUMIFS(Inputs_Class_Month!$F$5:$F$203,Inputs_Class_Month!$A$5:$A$203,$A7))/SUMIFS(Inputs_Class_Month!$D$5:$D$203,Inputs_Class_Month!$A$5:$A$203,$A7)) -> 0.70165746
A8: 2024-12 | B8: =IF(SUMIFS(Inputs_Class_Month!$D$5:$D$203,Inputs_Class_Month!$A$5:$A$203,$A8,Inputs_Class_Month!$B$5:$B$203,B$4)=0,"",(SUMIFS(Inputs_Class_Month!$E$5:$E$203,Inputs_Class_Month!$A$5:$A$203,$A8,Inputs_Class_Month!$B$5:$B$203,B$4)+Settings!$B$3*SUMIFS(Inputs_Class_Month!$F$5:$F$203,Inputs_Class_Month!$A$5:$A$203,$A8,Inputs_Class_Month!$B$5:$B$203,B$4))/SUMIFS(Inputs_Class_Month!$D$5:$D$203,Inputs_Class_Month!$A$5:$A$203,$A8,Inputs_Class_Month!$B$5:$B$203,B$4)) -> 0.68011696 | C8: =IF(SUMIFS(Inputs_Class_Month!$D$5:$D$203,Inputs_Class_Month!$A$5:$A$203,$A8,Inputs_Class_Month!$B$5:$B$203,C$4)=0,"",(SUMIFS(Inputs_Class_Month!$E$5:$E$203,Inputs_Class_Month!$A$5:$A$203,$A8,Inputs_Class_Month!$B$5:$B$203,C$4)+Settings!$B$3*SUMIFS(Inputs_Class_Month!$F$5:$F$203,Inputs_Class_Month!$A$5:$A$203,$A8,Inputs_Class_Month!$B$5:$B$203,C$4))/SUMIFS(Inputs_Class_Month!$D$5:$D$203,Inputs_Class_Month!$A$5:$A$203,$A8,Inputs_Class_Month!$B$5:$B$203,C$4)) -> 0.68492647 | D8: =IF(SUMIFS(Inputs_Class_Month!$D$5:$D$203,Inputs_Class_Month!$A$5:$A$203,$A8,Inputs_Class_Month!$B$5:$B$203,D$4)=0,"",(SUMIFS(Inputs_Class_Month!$E$5:$E$203,Inputs_Class_Month!$A$5:$A$203,$A8,Inputs_Class_Month!$B$5:$B$203,D$4)+Settings!$B$3*SUMIFS(Inputs_Class_Month!$F$5:$F$203,Inputs_Class_Month!$A$5:$A$203,$A8,Inputs_Class_Month!$B$5:$B$203,D$4))/SUMIFS(Inputs_Class_Month!$D$5:$D$203,Inputs_Class_Month!$A$5:$A$203,$A8,Inputs_Class_Month!$B$5:$B$203,D$4)) -> 0.72771739 | E8: =IF(SUMIFS(Inputs_Class_Month!$D$5:$D$203,Inputs_Class_Month!$A$5:$A$203,$A8,Inputs_Class_Month!$B$5:$B$203,E$4)=0,"",(SUMIFS(Inputs_Class_Month!$E$5:$E$203,Inputs_Class_Month!$A$5:$A$203,$A8,Inputs_Class_Month!$B$5:$B$203,E$4)+Settings!$B$3*SUMIFS(Inputs_Class_Month!$F$5:$F$203,Inputs_Class_Month!$A$5:$A$203,$A8,Inputs_Class_Month!$B$5:$B$203,E$4))/SUMIFS(Inputs_Class_Month!$D$5:$D$203,Inputs_Class_Month!$A$5:$A$203,$A8,Inputs_Class_Month!$B$5:$B$203,E$4)) | F8: =IF(SUMIFS(Inputs_Class_Month!$D$5:$D$203,Inputs_Class_Month!$A$5:$A$203,$A8,Inputs_Class_Month!$B$5:$B$203,F$4)=0,"",(SUMIFS(Inputs_Class_Month!$E$5:$E$203,Inputs_Class_Month!$A$5:$A$203,$A8,Inputs_Class_Month!$B$5:$B$203,F$4)+Settings!$B$3*SUMIFS(Inputs_Class_Month!$F$5:$F$203,Inputs_Class_Month!$A$5:$A$203,$A8,Inputs_Class_Month!$B$5:$B$203,F$4))/SUMIFS(Inputs_Class_Month!$D$5:$D$203,Inputs_Class_Month!$A$5:$A$203,$A8,Inputs_Class_Month!$B$5:$B$203,F$4)) -> 0.375 | G8: =IF(SUMIFS(Inputs_Class_Month!$D$5:$D$203,Inputs_Class_Month!$A$5:$A$203,$A8,Inputs_Class_Month!$B$5:$B$203,G$4)=0,"",(SUMIFS(Inputs_Class_Month!$E$5:$E$203,Inputs_Class_Month!$A$5:$A$203,$A8,Inputs_Class_Month!$B$5:$B$203,G$4)+Settings!$B$3*SUMIFS(Inputs_Class_Month!$F$5:$F$203,Inputs_Class_Month!$A$5:$A$203,$A8,Inputs_Class_Month!$B$5:$B$203,G$4))/SUMIFS(Inputs_Class_Month!$D$5:$D$203,Inputs_Class_Month!$A$5:$A$203,$A8,Inputs_Class_Month!$B$5:$B$203,G$4)) -> 0.6155303 | H8: =IF(SUMIFS(Inputs_Class_Month!$D$5:$D$203,Inputs_Class_Month!$A$5:$A$203,$A8)=0,"",(SUMIFS(Inputs_Class_Month!$E$5:$E$203,Inputs_Class_Month!$A$5:$A$203,$A8)+Settings!$B$3*SUMIFS(Inputs_Class_Month!$F$5:$F$203,Inputs_Class_Month!$A$5:$A$203,$A8))/SUMIFS(Inputs_Class_Month!$D$5:$D$203,Inputs_Class_Month!$A$5:$A$203,$A8)) -> 0.66193057
A9: 2025-01 | B9: =IF(SUMIFS(Inputs_Class_Month!$D$5:$D$203,Inputs_Class_Month!$A$5:$A$203,$A9,Inputs_Class_Month!$B$5:$B$203,B$4)=0,"",(SUMIFS(Inputs_Class_Month!$E$5:$E$203,Inputs_Class_Month!$A$5:$A$203,$A9,Inputs_Class_Month!$B$5:$B$203,B$4)+Settings!$B$3*SUMIFS(Inputs_Class_Month!$F$5:$F$203,Inputs_Class_Month!$A$5:$A$203,$A9,Inputs_Class_Month!$B$5:$B$203,B$4))/SUMIFS(Inputs_Class_Month!$D$5:$D$203,Inputs_Class_Month!$A$5:$A$203,$A9,Inputs_Class_Month!$B$5:$B$203,B$4)) -> 0.71217494 | C9: =IF(SUMIFS(Inputs_Class_Month!$D$5:$D$203,Inputs_Class_Month!$A$5:$A$203,$A9,Inputs_Class_Month!$B$5:$B$203,C$4)=0,"",(SUMIFS(Inputs_Class_Month!$E$5:$E$203,Inputs_Class_Month!$A$5:$A$203,$A9,Inputs_Class_Month!$B$5:$B$203,C$4)+Settings!$B$3*SUMIFS(Inputs_Class_Month!$F$5:$F$203,Inputs_Class_Month!$A$5:$A$203,$A9,Inputs_Class_Month!$B$5:$B$203,C$4))/SUMIFS(Inputs_Class_Month!$D$5:$D$203,Inputs_Class_Month!$A$5:$A$203,$A9,Inputs_Class_Month!$B$5:$B$203,C$4)) -> 0.69936709 | D9: =IF(SUMIFS(Inputs_Class_Month!$D$5:$D$203,Inputs_Class_Month!$A$5:$A$203,$A9,Inputs_Class_Month!$B$5:$B$203,D$4)=0,"",(SUMIFS(Inputs_Class_Month!$E$5:$E$203,Inputs_Class_Month!$A$5:$A$203,$A9,Inputs_Class_Month!$B$5:$B$203,D$4)+Settings!$B$3*SUMIFS(Inputs_Class_Month!$F$5:$F$203,Inputs_Class_Month!$A$5:$A$203,$A9,Inputs_Class_Month!$B$5:$B$203,D$4))/SUMIFS(Inputs_Class_Month!$D$5:$D$203,Inputs_Class_Month!$A$5:$A$203,$A9,Inputs_Class_Month!$B$5:$B$203,D$4)) -> 0.55326087 | E9: =IF(SUMIFS(Inputs_Class_Month!$D$5:$D$203,Inputs_Class_Month!$A$5:$A$203,$A9,Inputs_Class_Month!$B$5:$B$203,E$4)=0,"",(SUMIFS(Inputs_Class_Month!$E$5:$E$203,Inputs_Class_Month!$A$5:$A$203,$A9,Inputs_Class_Month!$B$5:$B$203,E$4)+Settings!$B$3*SUMIFS(Inputs_Class_Month!$F$5:$F$203,Inputs_Class_Month!$A$5:$A$203,$A9,Inputs_Class_Month!$B$5:$B$203,E$4))/SUMIFS(Inputs_Class_Month!$D$5:$D$203,Inputs_Class_Month!$A$5:$A$203,$A9,Inputs_Class_Month!$B$5:$B$203,E$4)) | F9: =IF(SUMIFS(Inputs_Class_Month!$D$5:$D$203,Inputs_Class_Month!$A$5:$A$203,$A9,Inputs_Class_Month!$B$5:$B$203,F$4)=0,"",(SUMIFS(Inputs_Class_Month!$E$5:$E$203,Inputs_Class_Month!$A$5:$A$203,$A9,Inputs_Class_Month!$B$5:$B$203,F$4)+Settings!$B$3*SUMIFS(Inputs_Class_Month!$F$5:$F$203,Inputs_Class_Month!$A$5:$A$203,$A9,Inputs_Class_Month!$B$5:$B$203,F$4))/SUMIFS(Inputs_Class_Month!$D$5:$D$203,Inputs_Class_Month!$A$5:$A$203,$A9,Inputs_Class_Month!$B$5:$B$203,F$4)) -> 0.31410256 | G9: =IF(SUMIFS(Inputs_Class_Month!$D$5:$D$203,Inputs_Class_Month!$A$5:$A$203,$A9,Inputs_Class_Month!$B$5:$B$203,G$4)=0,"",(SUMIFS(Inputs_Class_Month!$E$5:$E$203,Inputs_Class_Month!$A$5:$A$203,$A9,Inputs_Class_Month!$B$5:$B$203,G$4)+Settings!$B$3*SUMIFS(Inputs_Class_Month!$F$5:$F$203,Inputs_Class_Month!$A$5:$A$203,$A9,Inputs_Class_Month!$B$5:$B$203,G$4))/SUMIFS(Inputs_Class_Month!$D$5:$D$203,Inputs_Class_Month!$A$5:$A$203,$A9,Inputs_Class_Month!$B$5:$B$203,G$4)) -> 0.69460979 | H9: =IF(SUMIFS(Inputs_Class_Month!$D$5:$D$203,Inputs_Class_Month!$A$5:$A$203,$A9)=0,"",(SUMIFS(Inputs_Class_Month!$E$5:$E$203,Inputs_Class_Month!$A$5:$A$203,$A9)+Settings!$B$3*SUMIFS(Inputs_Class_Month!$F$5:$F$203,Inputs_Class_Month!$A$5:$A$203,$A9))/SUMIFS(Inputs_Class_Month!$D$5:$D$203,Inputs_Class_Month!$A$5:$A$203,$A9)) -> 0.68907035
A10: 2025-02 | B10: =IF(SUMIFS(Inputs_Class_Month!$D$5:$D$203,Inputs_Class_Month!$A$5:$A$203,$A10,Inputs_Class_Month!$B$5:$B$203,B$4)=0,"",(SUMIFS(Inputs_Class_Month!$E$5:$E$203,Inputs_Class_Month!$A$5:$A$203,$A10,Inputs_Class_Month!$B$5:$B$203,B$4)+Settings!$B$3*SUMIFS(Inputs_Class_Month!$F$5:$F$203,Inputs_Class_Month!$A$5:$A$203,$A10,Inputs_Class_Month!$B$5:$B$203,B$4))/SUMIFS(Inputs_Class_Month!$D$5:$D$203,Inputs_Class_Month!$A$5:$A$203,$A10,Inputs_Class_Month!$B$5:$B$203,B$4)) -> 0.63977713 | C10: =IF(SUMIFS(Inputs_Class_Month!$D$5:$D$203,Inputs_Class_Month!$A$5:$A$203,$A10,Inputs_Class_Month!$B$5:$B$203,C$4)=0,"",(SUMIFS(Inputs_Class_Month!$E$5:$E$203,Inputs_Class_Month!$A$5:$A$203,$A10,Inputs_Class_Month!$B$5:$B$203,C$4)+Settings!$B$3*SUMIFS(Inputs_Class_Month!$F$5:$F$203,Inputs_Class_Month!$A$5:$A$203,$A10,Inputs_Class_Month!$B$5:$B$203,C$4))/SUMIFS(Inputs_Class_Month!$D$5:$D$203,Inputs_Class_Month!$A$5:$A$203,$A10,Inputs_Class_Month!$B$5:$B$203,C$4)) -> 0.70127467 | D10: =IF(SUMIFS(Inputs_Class_Month!$D$5:$D$203,Inputs_Class_Month!$A$5:$A$203,$A10,Inputs_Class_Month!$B$5:$B$203,D$4)=0,"",(SUMIFS(Inputs_Class_Month!$E$5:$E$203,Inputs_Class_Month!$A$5:$A$203,$A10,Inputs_Class_Month!$B$5:$B$203,D$4)+Settings!$B$3*SUMIFS(Inputs_Class_Month!$F$5:$F$203,Inputs_Class_Month!$A$5:$A$203,$A10,Inputs_Class_Month!$B$5:$B$203,D$4))/SUMIFS(Inputs_Class_Month!$D$5:$D$203,Inputs_Class_Month!$A$5:$A$203,$A10,Inputs_Class_Month!$B$5:$B$203,D$4)) -> 0.67490119 | E10: =IF(SUMIFS(Inputs_Class_Month!$D$5:$D$203,Inputs_Class_Month!$A$5:$A$203,$A10,Inputs_Class_Month!$B$5:$B$203,E$4)=0,"",(SUMIFS(Inputs_Class_Month!$E$5:$E$203,Inputs_Class_Month!$A$5:$A$203,$A10,Inputs_Class_Month!$B$5:$B$203,E$4)+Settings!$B$3*SUMIFS(Inputs_Class_Month!$F$5:$F$203,Inputs_Class_Month!$A$5:$A$203,$A10,Inputs_Class_Month!$B$5:$B$203,E$4))/SUMIFS(Inputs_Class_Month!$D$5:$D$203,Inputs_Class_Month!$A$5:$A$203,$A10,Inputs_Class_Month!$B$5:$B$203,E$4)) -> 0.54166667 | F10: =IF(SUMIFS(Inputs_Class_Month!$D$5:$D$203,Inputs_Class_Month!$A$5:$A$203,$A10,Inputs_Class_Month!$B$5:$B$203,F$4)=0,"",(SUMIFS(Inputs_Class_Month!$E$5:$E$203,Inputs_Class_Month!$A$5:$A$203,$A10,Inputs_Class_Month!$B$5:$B$203,F$4)+Settings!$B$3*SUMIFS(Inputs_Class_Month!$F$5:$F$203,Inputs_Class_Month!$A$5:$A$203,$A10,Inputs_Class_Month!$B$5:$B$203,F$4))/SUMIFS(Inputs_Class_Month!$D$5:$D$203,Inputs_Class_Month!$A$5:$A$203,$A10,Inputs_Class_Month!$B$5:$B$203,F$4)) -> 0.45384615 | G10: =IF(SUMIFS(Inputs_Class_Month!$D$5:$D$203,Inputs_Class_Month!$A$5:$A$203,$A10,Inputs_Class_Month!$B$5:$B$203,G$4)=0,"",(SUMIFS(Inputs_Class_Month!$E$5:$E$203,Inputs_Class_Month!$A$5:$A$203,$A10,Inputs_Class_Month!$B$5:$B$203,G$4)+Settings!$B$3*SUMIFS(Inputs_Class_Month!$F$5:$F$203,Inputs_Class_Month!$A$5:$A$203,$A10,Inputs_Class_Month!$B$5:$B$203,G$4))/SUMIFS(Inputs_Class_Month!$D$5:$D$203,Inputs_Class_Month!$A$5:$A$203,$A10,Inputs_Class_Month!$B$5:$B$203,G$4)) -> 0.62868481 | H10: =IF(SUMIFS(Inputs_Class_Month!$D$5:$D$203,Inputs_Class_Month!$A$5:$A$203,$A10)=0,"",(SUMIFS(Inputs_Class_Month!$E$5:$E$203,Inputs_Class_Month!$A$5:$A$203,$A10)+Settings!$B$3*SUMIFS(Inputs_Class_Month!$F$5:$F$203,Inputs_Class_Month!$A$5:$A$203,$A10))/SUMIFS(Inputs_Class_Month!$D$5:$D$203,Inputs_Class_Month!$A$5:$A$203,$A10)) -> 0.65109148
A11: 2025-03 | B11: =IF(SUMIFS(Inputs_Class_Month!$D$5:$D$203,Inputs_Class_Month!$A$5:$A$203,$A11,Inputs_Class_Month!$B$5:$B$203,B$4)=0,"",(SUMIFS(Inputs_Class_Month!$E$5:$E$203,Inputs_Class_Month!$A$5:$A$203,$A11,Inputs_Class_Month!$B$5:$B$203,B$4)+Settings!$B$3*SUMIFS(Inputs_Class_Month!$F$5:$F$203,Inputs_Class_Month!$A$5:$A$203,$A11,Inputs_Class_Month!$B$5:$B$203,B$4))/SUMIFS(Inputs_Class_Month!$D$5:$D$203,Inputs_Class_Month!$A$5:$A$203,$A11,Inputs_Class_Month!$B$5:$B$203,B$4)) -> 0.83301768 | C11: =IF(SUMIFS(Inputs_Class_Month!$D$5:$D$203,Inputs_Class_Month!$A$5:$A$203,$A11,Inputs_Class_Month!$B$5:$B$203,C$4)=0,"",(SUMIFS(Inputs_Class_Month!$E$5:$E$203,Inputs_Class_Month!$A$5:$A$203,$A11,Inputs_Class_Month!$B$5:$B$203,C$4)+Settings!$B$3*SUMIFS(Inputs_Class_Month!$F$5:$F$203,Inputs_Class_Month!$A$5:$A$203,$A11,Inputs_Class_Month!$B$5:$B$203,C$4))/SUMIFS(Inputs_Class_Month!$D$5:$D$203,Inputs_Class_Month!$A$5:$A$203,$A11,Inputs_Class_Month!$B$5:$B$203,C$4)) -> 0.82498095 | D11: =IF(SUMIFS(Inputs_Class_Month!$D$5:$D$203,Inputs_Class_Month!$A$5:$A$203,$A11,Inputs_Class_Month!$B$5:$B$203,D$4)=0,"",(SUMIFS(Inputs_Class_Month!$E$5:$E$203,Inputs_Class_Month!$A$5:$A$203,$A11,Inputs_Class_Month!$B$5:$B$203,D$4)+Settings!$B$3*SUMIFS(Inputs_Class_Month!$F$5:$F$203,Inputs_Class_Month!$A$5:$A$203,$A11,Inputs_Class_Month!$B$5:$B$203,D$4))/SUMIFS(Inputs_Class_Month!$D$5:$D$203,Inputs_Class_Month!$A$5:$A$203,$A11,Inputs_Class_Month!$B$5:$B$203,D$4)) -> 0.79211957 | E11: =IF(SUMIFS(Inputs_Class_Month!$D$5:$D$203,Inputs_Class_Month!$A$5:$A$203,$A11,Inputs_Class_Month!$B$5:$B$203,E$4)=0,"",(SUMIFS(Inputs_Class_Month!$E$5:$E$203,Inputs_Class_Month!$A$5:$A$203,$A11,Inputs_Class_Month!$B$5:$B$203,E$4)+Settings!$B$3*SUMIFS(Inputs_Class_Month!$F$5:$F$203,Inputs_Class_Month!$A$5:$A$203,$A11,Inputs_Class_Month!$B$5:$B$203,E$4))/SUMIFS(Inputs_Class_Month!$D$5:$D$203,Inputs_Class_Month!$A$5:$A$203,$A11,Inputs_Class_Month!$B$5:$B$203,E$4)) -> 0.64583333 | F11: =IF(SUMIFS(Inputs_Class_Month!$D$5:$D$203,Inputs_Class_Month!$A$5:$A$203,$A11,Inputs_Class_Month!$B$5:$B$203,F$4)=0,"",(SUMIFS(Inputs_Class_Month!$E$5:$E$203,Inputs_Class_Month!$A$5:$A$203,$A11,Inputs_Class_Month!$B$5:$B$203,F$4)+Settings!$B$3*SUMIFS(Inputs_Class_Month!$F$5:$F$203,Inputs_Class_Month!$A$5:$A$203,$A11,Inputs_Class_Month!$B$5:$B$203,F$4))/SUMIFS(Inputs_Class_Month!$D$5:$D$203,Inputs_Class_Month!$A$5:$A$203,$A11,Inputs_Class_Month!$B$5:$B$203,F$4)) -> 0.37179487 | G11: =IF(SUMIFS(Inputs_Class_Month!$D$5:$D$203,Inputs_Class_Month!$A$5:$A$203,$A11,Inputs_Class_Month!$B$5:$B$203,G$4)=0,"",(SUMIFS(Inputs_Class_Month!$E$5:$E$203,Inputs_Class_Month!$A$5:$A$203,$A11,Inputs_Class_Month!$B$5:$B$203,G$4)+Settings!$B$3*SUMIFS(Inputs_Class_Month!$F$5:$F$203,Inputs_Class_Month!$A$5:$A$203,$A11,Inputs_Class_Month!$B$5:$B$203,G$4))/SUMIFS(Inputs_Class_Month!$D$5:$D$203,Inputs_Class_Month!$A$5:$A$203,$A11,Inputs_Class_Month!$B$5:$B$203,G$4)) -> 0.73024691 | H11: =IF(SUMIFS(Inputs_Class_Month!$D$5:$D$203,Inputs_Class_Month!$A$5:$A$203,$A11)=0,"",(SUMIFS(Inputs_Class_Month!$E$5:$E$203,Inputs_Class_Month!$A$5:$A$203,$A11)+Settings!$B$3*SUMIFS(Inputs_Class_Month!$F$5:$F$203,Inputs_Class_Month!$A$5:$A$203,$A11))/SUMIFS(Inputs_Class_Month!$D$5:$D$203,Inputs_Class_Month!$A$5:$A$203,$A11)) -> 0.7935502
A12: 2025-04 | B12: =IF(SUMIFS(Inputs_Class_Month!$D$5:$D$203,Inputs_Class_Month!$A$5:$A$203,$A12,Inputs_Class_Month!$B$5:$B$203,B$4)=0,"",(SUMIFS(Inputs_Class_Month!$E$5:$E$203,Inputs_Class_Month!$A$5:$A$203,$A12,Inputs_Class_Month!$B$5:$B$203,B$4)+Settings!$B$3*SUMIFS(Inputs_Class_Month!$F$5:$F$203,Inputs_Class_Month!$A$5:$A$203,$A12,Inputs_Class_Month!$B$5:$B$203,B$4))/SUMIFS(Inputs_Class_Month!$D$5:$D$203,Inputs_Class_Month!$A$5:$A$203,$A12,Inputs_Class_Month!$B$5:$B$203,B$4)) -> 0.79166667 | C12: =IF(SUMIFS(Inputs_Class_Month!$D$5:$D$203,Inputs_Class_Month!$A$5:$A$203,$A12,Inputs_Class_Month!$B$5:$B$203,C$4)=0,"",(SUMIFS(Inputs_Class_Month!$E$5:$E$203,Inputs_Class_Month!$A$5:$A$203,$A12,Inputs_Class_Month!$B$5:$B$203,C$4)+Settings!$B$3*SUMIFS(Inputs_Class_Month!$F$5:$F$203,Inputs_Class_Month!$A$5:$A$203,$A12,Inputs_Class_Month!$B$5:$B$203,C$4))/SUMIFS(Inputs_Class_Month!$D$5:$D$203,Inputs_Class_Month!$A$5:$A$203,$A12,Inputs_Class_Month!$B$5:$B$203,C$4)) -> 0.82494213 | D12: =IF(SUMIFS(Inputs_Class_Month!$D$5:$D$203,Inputs_Class_Month!$A$5:$A$203,$A12,Inputs_Class_Month!$B$5:$B$203,D$4)=0,"",(SUMIFS(Inputs_Class_Month!$E$5:$E$203,Inputs_Class_Month!$A$5:$A$203,$A12,Inputs_Class_Month!$B$5:$B$203,D$4)+Settings!$B$3*SUMIFS(Inputs_Class_Month!$F$5:$F$203,Inputs_Class_Month!$A$5:$A$203,$A12,Inputs_Class_Month!$B$5:$B$203,D$4))/SUMIFS(Inputs_Class_Month!$D$5:$D$203,Inputs_Class_Month!$A$5:$A$203,$A12,Inputs_Class_Month!$B$5:$B$203,D$4)) -> 0.725 | E12: =IF(SUMIFS(Inputs_Class_Month!$D$5:$D$203,Inputs_Class_Month!$A$5:$A$203,$A12,Inputs_Class_Month!$B$5:$B$203,E$4)=0,"",(SUMIFS(Inputs_Class_Month!$E$5:$E$203,Inputs_Class_Month!$A$5:$A$203,$A12,Inputs_Class_Month!$B$5:$B$203,E$4)+Settings!$B$3*SUMIFS(Inputs_Class_Month!$F$5:$F$203,Inputs_Class_Month!$A$5:$A$203,$A12,Inputs_Class_Month!$B$5:$B$203,E$4))/SUMIFS(Inputs_Class_Month!$D$5:$D$203,Inputs_Class_Month!$A$5:$A$203,$A12,Inputs_Class_Month!$B$5:$B$203,E$4)) -> 1 | F12: =IF(SUMIFS(Inputs_Class_Month!$D$5:$D$203,Inputs_Class_Month!$A$5:$A$203,$A12,Inputs_Class_Month!$B$5:$B$203,F$4)=0,"",(SUMIFS(Inputs_Class_Month!$E$5:$E$203,Inputs_Class_Month!$A$5:$A$203,$A12,Inputs_Class_Month!$B$5:$B$203,F$4)+Settings!$B$3*SUMIFS(Inputs_Class_Month!$F$5:$F$203,Inputs_Class_Month!$A$5:$A$203,$A12,Inputs_Class_Month!$B$5:$B$203,F$4))/SUMIFS(Inputs_Class_Month!$D$5:$D$203,Inputs_Class_Month!$A$5:$A$203,$A12,Inputs_Class_Month!$B$5:$B$203,F$4)) -> 0.63076923 | G12: =IF(SUMIFS(Inputs_Class_Month!$D$5:$D$203,Inputs_Class_Month!$A$5:$A$203,$A12,Inputs_Class_Month!$B$5:$B$203,G$4)=0,"",(SUMIFS(Inputs_Class_Month!$E$5:$E$203,Inputs_Class_Month!$A$5:$A$203,$A12,Inputs_Class_Month!$B$5:$B$203,G$4)+Settings!$B$3*SUMIFS(Inputs_Class_Month!$F$5:$F$203,Inputs_Class_Month!$A$5:$A$203,$A12,Inputs_Class_Month!$B$5:$B$203,G$4))/SUMIFS(Inputs_Class_Month!$D$5:$D$203,Inputs_Class_Month!$A$5:$A$203,$A12,Inputs_Class_Month!$B$5:$B$203,G$4)) -> 0.72952279 | H12: =IF(SUMIFS(Inputs_Class_Month!$D$5:$D$203,Inputs_Class_Month!$A$5:$A$203,$A12)=0,"",(SUMIFS(Inputs_Class_Month!$E$5:$E$203,Inputs_Class_Month!$A$5:$A$203,$A12)+Settings!$B$3*SUMIFS(Inputs_Class_Month!$F$5:$F$203,Inputs_Class_Month!$A$5:$A$203,$A12))/SUMIFS(Inputs_Class_Month!$D$5:$D$203,Inputs_Class_Month!$A$5:$A$203,$A12)) -> 0.77566324
A13: 2025-05 | B13: =IF(SUMIFS(Inputs_Class_Month!$D$5:$D$203,Inputs_Class_Month!$A$5:$A$203,$A13,Inputs_Class_Month!$B$5:$B$203,B$4)=0,"",(SUMIFS(Inputs_Class_Month!$E$5:$E$203,Inputs_Class_Month!$A$5:$A$203,$A13,Inputs_Class_Month!$B$5:$B$203,B$4)+Settings!$B$3*SUMIFS(Inputs_Class_Month!$F$5:$F$203,Inputs_Class_Month!$A$5:$A$203,$A13,Inputs_Class_Month!$B$5:$B$203,B$4))/SUMIFS(Inputs_Class_Month!$D$5:$D$203,Inputs_Class_Month!$A$5:$A$203,$A13,Inputs_Class_Month!$B$5:$B$203,B$4)) -> 0.8853022 | C13: =IF(SUMIFS(Inputs_Class_Month!$D$5:$D$203,Inputs_Class_Month!$A$5:$A$203,$A13,Inputs_Class_Month!$B$5:$B$203,C$4)=0,"",(SUMIFS(Inputs_Class_Month!$E$5:$E$203,Inputs_Class_Month!$A$5:$A$203,$A13,Inputs_Class_Month!$B$5:$B$203,C$4)+Settings!$B$3*SUMIFS(Inputs_Class_Month!$F$5:$F$203,Inputs_Class_Month!$A$5:$A$203,$A13,Inputs_Class_Month!$B$5:$B$203,C$4))/SUMIFS(Inputs_Class_Month!$D$5:$D$203,Inputs_Class_Month!$A$5:$A$203,$A13,Inputs_Class_Month!$B$5:$B$203,C$4)) -> 0.92277644 | D13: =IF(SUMIFS(Inputs_Class_Month!$D$5:$D$203,Inputs_Class_Month!$A$5:$A$203,$A13,Inputs_Class_Month!$B$5:$B$203,D$4)=0,"",(SUMIFS(Inputs_Class_Month!$E$5:$E$203,Inputs_Class_Month!$A$5:$A$203,$A13,Inputs_Class_Month!$B$5:$B$203,D$4)+Settings!$B$3*SUMIFS(Inputs_Class_Month!$F$5:$F$203,Inputs_Class_Month!$A$5:$A$203,$A13,Inputs_Class_Month!$B$5:$B$203,D$4))/SUMIFS(Inputs_Class_Month!$D$5:$D$203,Inputs_Class_Month!$A$5:$A$203,$A13,Inputs_Class_Month!$B$5:$B$203,D$4)) -> 0.86909263 | E13: =IF(SUMIFS(Inputs_Class_Month!$D$5:$D$203,Inputs_Class_Month!$A$5:$A$203,$A13,Inputs_Class_Month!$B$5:$B$203,E$4)=0,"",(SUMIFS(Inputs_Class_Month!$E$5:$E$203,Inputs_Class_Month!$A$5:$A$203,$A13,Inputs_Class_Month!$B$5:$B$203,E$4)+Settings!$B$3*SUMIFS(Inputs_Class_Month!$F$5:$F$203,Inputs_Class_Month!$A$5:$A$203,$A13,Inputs_Class_Month!$B$5:$B$203,E$4))/SUMIFS(Inputs_Class_Month!$D$5:$D$203,Inputs_Class_Month!$A$5:$A$203,$A13,Inputs_Class_Month!$B$5:$B$203,E$4)) -> 0.83333333 | F13: =IF(SUMIFS(Inputs_Class_Month!$D$5:$D$203,Inputs_Class_Month!$A$5:$A$203,$A13,Inputs_Class_Month!$B$5:$B$203,F$4)=0,"",(SUMIFS(Inputs_Class_Month!$E$5:$E$203,Inputs_Class_Month!$A$5:$A$203,$A13,Inputs_Class_Month!$B$5:$B$203,F$4)+Settings!$B$3*SUMIFS(Inputs_Class_Month!$F$5:$F$203,Inputs_Class_Month!$A$5:$A$203,$A13,Inputs_Class_Month!$B$5:$B$203,F$4))/SUMIFS(Inputs_Class_Month!$D$5:$D$203,Inputs_Class_Month!$A$5:$A$203,$A13,Inputs_Class_Month!$B$5:$B$203,F$4)) -> 0.76923077 | G13: =IF(SUMIFS(Inputs_Class_Month!$D$5:$D$203,Inputs_Class_Month!$A$5:$A$203,$A13,Inputs_Class_Month!$B$5:$B$203,G$4)=0,"",(SUMIFS(Inputs_Class_Month!$E$5:$E$203,Inputs_Class_Month!$A$5:$A$203,$A13,Inputs_Class_Month!$B$5:$B$203,G$4)+Settings!$B$3*SUMIFS(Inputs_Class_Month!$F$5:$F$203,Inputs_Class_Month!$A$5:$A$203,$A13,Inputs_Class_Month!$B$5:$B$203,G$4))/SUMIFS(Inputs_Class_Month!$D$5:$D$203,Inputs_Class_Month!$A$5:$A$203,$A13,Inputs_Class_Month!$B$5:$B$203,G$4)) -> 0.90088384 | H13: =IF(SUMIFS(Inputs_Class_Month!$D$5:$D$203,Inputs_Class_Month!$A$5:$A$203,$A13)=0,"",(SUMIFS(Inputs_Class_Month!$E$5:$E$203,Inputs_Class_Month!$A$5:$A$203,$A13)+Settings!$B$3*SUMIFS(Inputs_Class_Month!$F$5:$F$203,Inputs_Class_Month!$A$5:$A$203,$A13))/SUMIFS(Inputs_Class_Month!$D$5:$D$203,Inputs_Class_Month!$A$5:$A$203,$A13)) -> 0.8964149
A14: 2025-06 | B14: =IF(SUMIFS(Inputs_Class_Month!$D$5:$D$203,Inputs_Class_Month!$A$5:$A$203,$A14,Inputs_Class_Month!$B$5:$B$203,B$4)=0,"",(SUMIFS(Inputs_Class_Month!$E$5:$E$203,Inputs_Class_Month!$A$5:$A$203,$A14,Inputs_Class_Month!$B$5:$B$203,B$4)+Settings!$B$3*SUMIFS(Inputs_Class_Month!$F$5:$F$203,Inputs_Class_Month!$A$5:$A$203,$A14,Inputs_Class_Month!$B$5:$B$203,B$4))/SUMIFS(Inputs_Class_Month!$D$5:$D$203,Inputs_Class_Month!$A$5:$A$203,$A14,Inputs_Class_Month!$B$5:$B$203,B$4)) -> 0.74660165 | C14: =IF(SUMIFS(Inputs_Class_Month!$D$5:$D$203,Inputs_Class_Month!$A$5:$A$203,$A14,Inputs_Class_Month!$B$5:$B$203,C$4)=0,"",(SUMIFS(Inputs_Class_Month!$E$5:$E$203,Inputs_Class_Month!$A$5:$A$203,$A14,Inputs_Class_Month!$B$5:$B$203,C$4)+Settings!$B$3*SUMIFS(Inputs_Class_Month!$F$5:$F$203,Inputs_Class_Month!$A$5:$A$203,$A14,Inputs_Class_Month!$B$5:$B$203,C$4))/SUMIFS(Inputs_Class_Month!$D$5:$D$203,Inputs_Class_Month!$A$5:$A$203,$A14,Inputs_Class_Month!$B$5:$B$203,C$4)) -> 0.73468339 | D14: =IF(SUMIFS(Inputs_Class_Month!$D$5:$D$203,Inputs_Class_Month!$A$5:$A$203,$A14,Inputs_Class_Month!$B$5:$B$203,D$4)=0,"",(SUMIFS(Inputs_Class_Month!$E$5:$E$203,Inputs_Class_Month!$A$5:$A$203,$A14,Inputs_Class_Month!$B$5:$B$203,D$4)+Settings!$B$3*SUMIFS(Inputs_Class_Month!$F$5:$F$203,Inputs_Class_Month!$A$5:$A$203,$A14,Inputs_Class_Month!$B$5:$B$203,D$4))/SUMIFS(Inputs_Class_Month!$D$5:$D$203,Inputs_Class_Month!$A$5:$A$203,$A14,Inputs_Class_Month!$B$5:$B$203,D$4)) -> 0.74407115 | E14: =IF(SUMIFS(Inputs_Class_Month!$D$5:$D$203,Inputs_Class_Month!$A$5:$A$203,$A14,Inputs_Class_Month!$B$5:$B$203,E$4)=0,"",(SUMIFS(Inputs_Class_Month!$E$5:$E$203,Inputs_Class_Month!$A$5:$A$203,$A14,Inputs_Class_Month!$B$5:$B$203,E$4)+Settings!$B$3*SUMIFS(Inputs_Class_Month!$F$5:$F$203,Inputs_Class_Month!$A$5:$A$203,$A14,Inputs_Class_Month!$B$5:$B$203,E$4))/SUMIFS(Inputs_Class_Month!$D$5:$D$203,Inputs_Class_Month!$A$5:$A$203,$A14,Inputs_Class_Month!$B$5:$B$203,E$4)) -> 0.95833333 | F14: =IF(SUMIFS(Inputs_Class_Month!$D$5:$D$203,Inputs_Class_Month!$A$5:$A$203,$A14,Inputs_Class_Month!$B$5:$B$203,F$4)=0,"",(SUMIFS(Inputs_Class_Month!$E$5:$E$203,Inputs_Class_Month!$A$5:$A$203,$A14,Inputs_Class_Month!$B$5:$B$203,F$4)+Settings!$B$3*SUMIFS(Inputs_Class_Month!$F$5:$F$203,Inputs_Class_Month!$A$5:$A$203,$A14,Inputs_Class_Month!$B$5:$B$203,F$4))/SUMIFS(Inputs_Class_Month!$D$5:$D$203,Inputs_Class_Month!$A$5:$A$203,$A14,Inputs_Class_Month!$B$5:$B$203,F$4)) -> 0.48717949 | G14: =IF(SUMIFS(Inputs_Class_Month!$D$5:$D$203,Inputs_Class_Month!$A$5:$A$203,$A14,Inputs_Class_Month!$B$5:$B$203,G$4)=0,"",(SUMIFS(Inputs_Class_Month!$E$5:$E$203,Inputs_Class_Month!$A$5:$A$203,$A14,Inputs_Class_Month!$B$5:$B$203,G$4)+Settings!$B$3*SUMIFS(Inputs_Class_Month!$F$5:$F$203,Inputs_Class_Month!$A$5:$A$203,$A14,Inputs_Class_Month!$B$5:$B$203,G$4))/SUMIFS(Inputs_Class_Month!$D$5:$D$203,Inputs_Class_Month!$A$5:$A$203,$A14,Inputs_Class_Month!$B$5:$B$203,G$4)) -> 0.68755383 | H14: =IF(SUMIFS(Inputs_Class_Month!$D$5:$D$203,Inputs_Class_Month!$A$5:$A$203,$A14)=0,"",(SUMIFS(Inputs_Class_Month!$E$5:$E$203,Inputs_Class_Month!$A$5:$A$203,$A14)+Settings!$B$3*SUMIFS(Inputs_Class_Month!$F$5:$F$203,Inputs_Class_Month!$A$5:$A$203,$A14))/SUMIFS(Inputs_Class_Month!$D$5:$D$203,Inputs_Class_Month!$A$5:$A$203,$A14)) -> 0.72541218
A15: 2025-07 | B15: =IF(SUMIFS(Inputs_Class_Month!$D$5:$D$203,Inputs_Class_Month!$A$5:$A$203,$A15,Inputs_Class_Month!$B$5:$B$203,B$4)=0,"",(SUMIFS(Inputs_Class_Month!$E$5:$E$203,Inputs_Class_Month!$A$5:$A$203,$A15,Inputs_Class_Month!$B$5:$B$203,B$4)+Settings!$B$3*SUMIFS(Inputs_Class_Month!$F$5:$F$203,Inputs_Class_Month!$A$5:$A$203,$A15,Inputs_Class_Month!$B$5:$B$203,B$4))/SUMIFS(Inputs_Class_Month!$D$5:$D$203,Inputs_Class_Month!$A$5:$A$203,$A15,Inputs_Class_Month!$B$5:$B$203,B$4)) -> 0.77001195 | C15: =IF(SUMIFS(Inputs_Class_Month!$D$5:$D$203,Inputs_Class_Month!$A$5:$A$203,$A15,Inputs_Class_Month!$B$5:$B$203,C$4)=0,"",(SUMIFS(Inputs_Class_Month!$E$5:$E$203,Inputs_Class_Month!$A$5:$A$203,$A15,Inputs_Class_Month!$B$5:$B$203,C$4)+Settings!$B$3*SUMIFS(Inputs_Class_Month!$F$5:$F$203,Inputs_Class_Month!$A$5:$A$203,$A15,Inputs_Class_Month!$B$5:$B$203,C$4))/SUMIFS(Inputs_Class_Month!$D$5:$D$203,Inputs_Class_Month!$A$5:$A$203,$A15,Inputs_Class_Month!$B$5:$B$203,C$4)) -> 0.67474288 | D15: =IF(SUMIFS(Inputs_Class_Month!$D$5:$D$203,Inputs_Class_Month!$A$5:$A$203,$A15,Inputs_Class_Month!$B$5:$B$203,D$4)=0,"",(SUMIFS(Inputs_Class_Month!$E$5:$E$203,Inputs_Class_Month!$A$5:$A$203,$A15,Inputs_Class_Month!$B$5:$B$203,D$4)+Settings!$B$3*SUMIFS(Inputs_Class_Month!$F$5:$F$203,Inputs_Class_Month!$A$5:$A$203,$A15,Inputs_Class_Month!$B$5:$B$203,D$4))/SUMIFS(Inputs_Class_Month!$D$5:$D$203,Inputs_Class_Month!$A$5:$A$203,$A15,Inputs_Class_Month!$B$5:$B$203,D$4)) -> 0.60474308 | E15: =IF(SUMIFS(Inputs_Class_Month!$D$5:$D$203,Inputs_Class_Month!$A$5:$A$203,$A15,Inputs_Class_Month!$B$5:$B$203,E$4)=0,"",(SUMIFS(Inputs_Class_Month!$E$5:$E$203,Inputs_Class_Month!$A$5:$A$203,$A15,Inputs_Class_Month!$B$5:$B$203,E$4)+Settings!$B$3*SUMIFS(Inputs_Class_Month!$F$5:$F$203,Inputs_Class_Month!$A$5:$A$203,$A15,Inputs_Class_Month!$B$5:$B$203,E$4))/SUMIFS(Inputs_Class_Month!$D$5:$D$203,Inputs_Class_Month!$A$5:$A$203,$A15,Inputs_Class_Month!$B$5:$B$203,E$4)) -> 0.45833333 | F15: =IF(SUMIFS(Inputs_Class_Month!$D$5:$D$203,Inputs_Class_Month!$A$5:$A$203,$A15,Inputs_Class_Month!$B$5:$B$203,F$4)=0,"",(SUMIFS(Inputs_Class_Month!$E$5:$E$203,Inputs_Class_Month!$A$5:$A$203,$A15,Inputs_Class_Month!$B$5:$B$203,F$4)+Settings!$B$3*SUMIFS(Inputs_Class_Month!$F$5:$F$203,Inputs_Class_Month!$A$5:$A$203,$A15,Inputs_Class_Month!$B$5:$B$203,F$4))/SUMIFS(Inputs_Class_Month!$D$5:$D$203,Inputs_Class_Month!$A$5:$A$203,$A15,Inputs_Class_Month!$B$5:$B$203,F$4)) -> 0.41025641 | G15: =IF(SUMIFS(Inputs_Class_Month!$D$5:$D$203,Inputs_Class_Month!$A$5:$A$203,$A15,Inputs_Class_Month!$B$5:$B$203,G$4)=0,"",(SUMIFS(Inputs_Class_Month!$E$5:$E$203,Inputs_Class_Month!$A$5:$A$203,$A15,Inputs_Class_Month!$B$5:$B$203,G$4)+Settings!$B$3*SUMIFS(Inputs_Class_Month!$F$5:$F$203,Inputs_Class_Month!$A$5:$A$203,$A15,Inputs_Class_Month!$B$5:$B$203,G$4))/SUMIFS(Inputs_Class_Month!$D$5:$D$203,Inputs_Class_Month!$A$5:$A$203,$A15,Inputs_Class_Month!$B$5:$B$203,G$4)) -> 0.59560724 | H15: =IF(SUMIFS(Inputs_Class_Month!$D$5:$D$203,Inputs_Class_Month!$A$5:$A$203,$A15)=0,"",(SUMIFS(Inputs_Class_Month!$E$5:$E$203,Inputs_Class_Month!$A$5:$A$203,$A15)+Settings!$B$3*SUMIFS(Inputs_Class_Month!$F$5:$F$203,Inputs_Class_Month!$A$5:$A$203,$A15))/SUMIFS(Inputs_Class_Month!$D$5:$D$203,Inputs_Class_Month!$A$5:$A$203,$A15)) -> 0.67868715
